2025-04-17 09:47:05 [ERROR]: Resolved 'Current Display' to actual column: Original_Text
2025-04-17 09:47:15 [ERROR]: Starting CSV export process
2025-04-17 09:47:15 [ERROR]: Ensuring these columns exist in the DataFrame: ['Page', 'Text', 'Citation', 'Document_Type', 'Author', 'Correspondent', 'Correspondent_Place', 'Date', 'Place_of_Creation', 'People', 'Places', 'Summary', 'People', 'Places', 'Translation', 'Separated_Text', 'Creation_Place', 'Date']
2025-04-17 09:47:15 [ERROR]: Added missing column: Place_of_Creation
2025-04-17 09:47:15 [ERROR]: Added missing column: Text
2025-04-17 09:47:15 [ERROR]: Using resolved text source column: Original_Text
2025-04-17 09:47:15 [ERROR]: Reset index for temp_df. New length: 335
2025-04-17 09:48:04 [ERROR]: API returned error for index 151, job Metadata
2025-04-17 09:48:04 [ERROR]: API returned error for index 152, job Metadata
2025-04-17 09:48:04 [ERROR]: API returned error for index 154, job Metadata
2025-04-17 09:48:04 [ERROR]: API returned error for index 153, job Metadata
2025-04-17 09:48:05 [ERROR]: API returned error for index 156, job Metadata
2025-04-17 09:48:05 [ERROR]: API returned error for index 159, job Metadata
2025-04-17 09:48:06 [ERROR]: API returned error for index 166, job Metadata
2025-04-17 09:48:07 [ERROR]: API returned error for index 172, job Metadata
2025-04-17 09:48:43 [ERROR]: API returned error for index 312, job Metadata
2025-04-17 09:48:43 [ERROR]: API returned error for index 313, job Metadata
2025-04-17 09:48:43 [ERROR]: API returned error for index 314, job Metadata
2025-04-17 09:48:44 [ERROR]: API returned error for index 316, job Metadata
2025-04-17 09:48:44 [ERROR]: API returned error for index 315, job Metadata
2025-04-17 09:48:44 [ERROR]: API returned error for index 318, job Metadata
2025-04-17 09:48:44 [ERROR]: API returned error for index 317, job Metadata
2025-04-17 09:48:44 [ERROR]: API returned error for index 319, job Metadata
2025-04-17 09:48:44 [ERROR]: API returned error for index 320, job Metadata
2025-04-17 09:48:44 [ERROR]: API returned error for index 321, job Metadata
2025-04-17 09:48:45 [ERROR]: API returned error for index 322, job Metadata
2025-04-17 09:48:45 [ERROR]: API returned error for index 323, job Metadata
2025-04-17 09:48:45 [ERROR]: API returned error for index 325, job Metadata
2025-04-17 09:48:45 [ERROR]: API returned error for index 324, job Metadata
2025-04-17 09:48:46 [ERROR]: API returned error for index 326, job Metadata
2025-04-17 09:48:46 [ERROR]: API returned error for index 328, job Metadata
2025-04-17 09:48:46 [ERROR]: API returned error for index 329, job Metadata
2025-04-17 09:48:46 [ERROR]: API returned error for index 331, job Metadata
2025-04-17 09:48:46 [ERROR]: API returned error for index 327, job Metadata
2025-04-17 09:48:46 [ERROR]: API returned error for index 333, job Metadata
2025-04-17 09:48:46 [ERROR]: API returned error for index 332, job Metadata
2025-04-17 09:48:46 [ERROR]: API returned error for index 334, job Metadata
2025-04-17 09:48:46 [ERROR]: API returned error for index 330, job Metadata
2025-04-17 09:49:59 [ERROR]: Restored original index to updated_df for alignment.
2025-04-17 09:49:59 [ERROR]: Using metadata headers from preset 'Standard Metadata': Document Type;Author;Correspondent;Correspondent Place;Date;Place of Creation;People;Places;Summary
2025-04-17 09:49:59 [ERROR]: Added essential column: Creation_Place
2025-04-17 09:49:59 [ERROR]: Metadata columns to copy: ['Document_Type', 'Author', 'Correspondent', 'Correspondent_Place', 'Date', 'Place_of_Creation', 'People', 'Places', 'Summary', 'Creation_Place']
2025-04-17 09:49:59 [ERROR]: Copied 335 values for column: Document_Type
2025-04-17 09:49:59 [ERROR]: Copied 335 values for column: Author
2025-04-17 09:49:59 [ERROR]: Copied 335 values for column: Correspondent
2025-04-17 09:49:59 [ERROR]: Copied 335 values for column: Correspondent_Place
2025-04-17 09:49:59 [ERROR]: Copied 335 values for column: Date
2025-04-17 09:49:59 [ERROR]: Copied 335 values for column: Place_of_Creation
2025-04-17 09:49:59 [ERROR]: Copied 335 values for column: People
2025-04-17 09:49:59 [ERROR]: Copied 335 values for column: Places
2025-04-17 09:49:59 [ERROR]: Copied 335 values for column: Summary
2025-04-17 09:49:59 [ERROR]: Copied 335 values for column: Creation_Place
2025-04-17 09:49:59 [ERROR]: Single author specified: Angus Bethune
2025-04-17 09:49:59 [ERROR]: Citation specified: HBCA, B194-A-2
2025-04-17 09:49:59 [ERROR]: Starting date and place analysis sequence using preset: Sequence_Diary
2025-04-17 09:49:59 [ERROR]: Using required headers from sequential preset: ['Date', 'Place', 'Author']
2025-04-17 09:49:59 [ERROR]: Clearing existing values for fresh date analysis
2025-04-17 09:49:59 [ERROR]: Copied existing Date values from compiled_df to date_df
2025-04-17 09:49:59 [ERROR]: Copied existing Author values from compiled_df to date_df
2025-04-17 09:49:59 [ERROR]: Added legacy Creation_Place column to date_df
2025-04-17 09:49:59 [ERROR]: Created date analysis dataframe with 335 rows and columns: ['Page', 'Text', 'Date', 'Place', 'Author', 'Creation_Place']
2025-04-17 09:49:59 [ERROR]: Using specified sequential preset: Sequence_Diary
2025-04-17 09:49:59 [ERROR]: Found required headers in sequence preset: ['Date', 'Place', 'Author']
2025-04-17 09:49:59 [ERROR]: Setting active sequential preset to: Sequence_Diary
2025-04-17 09:50:09 [ERROR]: Date analysis result dataframe has columns: ['Page', 'Text', 'Date', 'Place', 'Author', 'Creation_Place']
2025-04-17 09:50:09 [ERROR]: Date analysis result dataframe has 335 rows
2025-04-17 09:50:09 [ERROR]: Date analysis found 0 dates
2025-04-17 09:50:09 [ERROR]: Date analysis found 0 Date values
2025-04-17 09:50:09 [ERROR]: Date analysis found 0 Place values
2025-04-17 09:50:09 [ERROR]: Date analysis found 0 Author values
2025-04-17 09:50:09 [ERROR]: Sample row 0: {'Page': 0, 'Text': '1826/05/01 Monday: Raining throughout the mechanics were working at the Bridge'}
2025-04-17 09:50:09 [ERROR]: Sample row 1: {'Page': 1, 'Text': '1826/05/02 Tuesday: Rainy weather the mechanics were at the same Work. De Somme has been to day and yesterday removing Timber. I had the Scow which was sinking in the Creek Cleared of ice and water'}
2025-04-17 09:50:09 [ERROR]: Sample row 2: {'Page': 2, 'Text': '1826/05/03 Wednesday: Rainy weather in the forenoon a fine evening. The mechanics were at the Bridge and also employed the scow of water which got into it last night.'}
2025-04-17 09:50:09 [ERROR]: Date analysis returned dataframe with columns: Page, Text, Date, Place, Author, Creation_Place
2025-04-17 09:50:09 [ERROR]: Sample row 0: {'Page': 0, 'Text': '1826/05/01 Monday: Raining throughout the mechanics were working at the Bridge', 'Date': '', 'Place': '', 'Author': '', 'Creation_Place': ''}
2025-04-17 09:50:09 [ERROR]: Sample row 1: {'Page': 1, 'Text': '1826/05/02 Tuesday: Rainy weather the mechanics were at the same Work. De Somme has been to day and yesterday removing Timber. I had the Scow which was sinking in the Creek Cleared of ice and water', 'Date': '', 'Place': '', 'Author': '', 'Creation_Place': ''}
2025-04-17 09:50:09 [ERROR]: Sample row 2: {'Page': 2, 'Text': '1826/05/03 Wednesday: Rainy weather in the forenoon a fine evening. The mechanics were at the Bridge and also employed the scow of water which got into it last night.', 'Date': '', 'Place': '', 'Author': '', 'Creation_Place': ''}
2025-04-17 09:50:09 [ERROR]: Date and place analysis failed: invalid command name ".!toplevel10.!label"
Stack trace:
Traceback (most recent call last):
  File "d:\TranscriptionPearl\TranscriptionPearl\util\ExportFunctions.py", line 846, in _analyze_dates_sequentially
    progress_label.config(text="Finalizing date and place analysis...")
  File "C:\Users\mark_\anaconda3\envs\DocExtractor\Lib\tkinter\__init__.py", line 1702, in configure
    return self._configure('configure', cnf, kw)
           ^^^^^^^^^^^^^^^^^^^^^^^^^^^^^^^^^^^^^
  File "C:\Users\mark_\anaconda3\envs\DocExtractor\Lib\tkinter\__init__.py", line 1692, in _configure
    self.tk.call(_flatten((self._w, cmd)) + self._options(cnf))
_tkinter.TclError: invalid command name ".!toplevel10.!label"
2025-04-17 09:50:11 [ERROR]: Sequential preset headers: ['Date', 'Place', 'Author']
2025-04-17 09:50:11 [ERROR]: Preparing export dataframe. Text source: Original_Text
2025-04-17 09:50:11 [ERROR]: Using column 'Original_Text' for text
2025-04-17 09:50:11 [ERROR]: Overriding 'Author' column with single author: Angus Bethune
2025-04-17 09:50:11 [ERROR]: Metadata headers from preset 'Standard Metadata': ['Document_Type', 'Author', 'Correspondent', 'Correspondent_Place', 'Date', 'Place_of_Creation', 'People', 'Places', 'Summary']
2025-04-17 09:50:11 [ERROR]: Adding/overwriting with sequential headers: ['Date', 'Place', 'Author']
2025-04-17 09:50:11 [ERROR]: Sequential header 'Place' not found in compiled data.
2025-04-17 09:50:11 [ERROR]: Adding 'Citation' column.
2025-04-17 09:50:11 [ERROR]: Final ordered columns for export: ['Page', 'Author', 'Document_Type', 'Correspondent', 'Correspondent_Place', 'Date', 'Place_of_Creation', 'People', 'Places', 'Summary', 'Original_Text', 'Citation']
2025-04-17 09:50:24 [ERROR]: Failed to export text: '_tkinter.tkapp' object has no attribute 'find_right_text'
Stack trace:
Traceback (most recent call last):
  File "d:\TranscriptionPearl\TranscriptionPearl\util\ExportFunctions.py", line 47, in export
    text = self.app.find_right_text(index)
           ^^^^^^^^^^^^^^^^^^^^^^^^
  File "C:\Users\mark_\anaconda3\envs\DocExtractor\Lib\tkinter\__init__.py", line 2411, in __getattr__
    return getattr(self.tk, attr)
           ^^^^^^^^^^^^^^^^^^^^^^
AttributeError: '_tkinter.tkapp' object has no attribute 'find_right_text'
2025-04-17 09:51:23 [ERROR]: Failed to export text: '_tkinter.tkapp' object has no attribute 'find_right_text'
Stack trace:
Traceback (most recent call last):
  File "d:\TranscriptionPearl\TranscriptionPearl\util\ExportFunctions.py", line 47, in export
    text = self.app.find_right_text(index)
           ^^^^^^^^^^^^^^^^^^^^^^^^
  File "C:\Users\mark_\anaconda3\envs\DocExtractor\Lib\tkinter\__init__.py", line 2411, in __getattr__
    return getattr(self.tk, attr)
           ^^^^^^^^^^^^^^^^^^^^^^
AttributeError: '_tkinter.tkapp' object has no attribute 'find_right_text'
2025-04-18 09:13:17 [ERROR]: Enabled Names highlighting due to existing People data
2025-04-18 09:26:47 [ERROR]: Enabled Names highlighting due to existing People data
2025-04-18 09:45:17 [ERROR]: Enabled Names highlighting due to existing People data
2025-04-18 09:49:09 [ERROR]: Enabled Names highlighting due to existing People data
2025-04-18 09:53:33 [ERROR]: Enabled Names highlighting due to existing People data
2025-04-18 12:43:52 [ERROR]: Enabled Names highlighting due to existing People data
2025-04-18 12:45:36 [ERROR]: Enabled Names highlighting due to existing People data
2025-04-18 12:50:53 [ERROR]: Enabled Names highlighting due to existing People data
2025-04-18 13:07:22 [ERROR]: Enabled Names highlighting due to existing People data
2025-04-18 13:07:22 [ERROR]: Enabled Places highlighting due to existing Places data
2025-04-18 13:11:53 [ERROR]: Enabled Names highlighting due to existing People data
2025-04-18 13:11:53 [ERROR]: Enabled Places highlighting due to existing Places data
2025-04-18 13:16:54 [ERROR]: Enabled Names highlighting due to existing People data
2025-04-18 13:16:54 [ERROR]: Enabled Places highlighting due to existing Places data
