2025-04-17 09:47:05 [ERROR]: Resolved 'Current Display' to actual column: Original_Text
2025-04-17 09:47:15 [ERROR]: Starting CSV export process
2025-04-17 09:47:15 [ERROR]: Ensuring these columns exist in the DataFrame: ['Page', 'Text', 'Citation', 'Document_Type', 'Author', 'Correspondent', 'Correspondent_Place', 'Date', 'Place_of_Creation', 'People', 'Places', 'Summary', 'People', 'Places', 'Translation', 'Separated_Text', 'Creation_Place', 'Date']
2025-04-17 09:47:15 [ERROR]: Added missing column: Place_of_Creation
2025-04-17 09:47:15 [ERROR]: Added missing column: Text
2025-04-17 09:47:15 [ERROR]: Using resolved text source column: Original_Text
2025-04-17 09:47:15 [ERROR]: Reset index for temp_df. New length: 335
2025-04-17 09:48:04 [ERROR]: API returned error for index 151, job Metadata
2025-04-17 09:48:04 [ERROR]: API returned error for index 152, job Metadata
2025-04-17 09:48:04 [ERROR]: API returned error for index 154, job Metadata
2025-04-17 09:48:04 [ERROR]: API returned error for index 153, job Metadata
2025-04-17 09:48:05 [ERROR]: API returned error for index 156, job Metadata
2025-04-17 09:48:05 [ERROR]: API returned error for index 159, job Metadata
2025-04-17 09:48:06 [ERROR]: API returned error for index 166, job Metadata
2025-04-17 09:48:07 [ERROR]: API returned error for index 172, job Metadata
2025-04-17 09:48:43 [ERROR]: API returned error for index 312, job Metadata
2025-04-17 09:48:43 [ERROR]: API returned error for index 313, job Metadata
2025-04-17 09:48:43 [ERROR]: API returned error for index 314, job Metadata
2025-04-17 09:48:44 [ERROR]: API returned error for index 316, job Metadata
2025-04-17 09:48:44 [ERROR]: API returned error for index 315, job Metadata
2025-04-17 09:48:44 [ERROR]: API returned error for index 318, job Metadata
2025-04-17 09:48:44 [ERROR]: API returned error for index 317, job Metadata
2025-04-17 09:48:44 [ERROR]: API returned error for index 319, job Metadata
2025-04-17 09:48:44 [ERROR]: API returned error for index 320, job Metadata
2025-04-17 09:48:44 [ERROR]: API returned error for index 321, job Metadata
2025-04-17 09:48:45 [ERROR]: API returned error for index 322, job Metadata
2025-04-17 09:48:45 [ERROR]: API returned error for index 323, job Metadata
2025-04-17 09:48:45 [ERROR]: API returned error for index 325, job Metadata
2025-04-17 09:48:45 [ERROR]: API returned error for index 324, job Metadata
2025-04-17 09:48:46 [ERROR]: API returned error for index 326, job Metadata
2025-04-17 09:48:46 [ERROR]: API returned error for index 328, job Metadata
2025-04-17 09:48:46 [ERROR]: API returned error for index 329, job Metadata
2025-04-17 09:48:46 [ERROR]: API returned error for index 331, job Metadata
2025-04-17 09:48:46 [ERROR]: API returned error for index 327, job Metadata
2025-04-17 09:48:46 [ERROR]: API returned error for index 333, job Metadata
2025-04-17 09:48:46 [ERROR]: API returned error for index 332, job Metadata
2025-04-17 09:48:46 [ERROR]: API returned error for index 334, job Metadata
2025-04-17 09:48:46 [ERROR]: API returned error for index 330, job Metadata
2025-04-17 09:49:59 [ERROR]: Restored original index to updated_df for alignment.
2025-04-17 09:49:59 [ERROR]: Using metadata headers from preset 'Standard Metadata': Document Type;Author;Correspondent;Correspondent Place;Date;Place of Creation;People;Places;Summary
2025-04-17 09:49:59 [ERROR]: Added essential column: Creation_Place
2025-04-17 09:49:59 [ERROR]: Metadata columns to copy: ['Document_Type', 'Author', 'Correspondent', 'Correspondent_Place', 'Date', 'Place_of_Creation', 'People', 'Places', 'Summary', 'Creation_Place']
2025-04-17 09:49:59 [ERROR]: Copied 335 values for column: Document_Type
2025-04-17 09:49:59 [ERROR]: Copied 335 values for column: Author
2025-04-17 09:49:59 [ERROR]: Copied 335 values for column: Correspondent
2025-04-17 09:49:59 [ERROR]: Copied 335 values for column: Correspondent_Place
2025-04-17 09:49:59 [ERROR]: Copied 335 values for column: Date
2025-04-17 09:49:59 [ERROR]: Copied 335 values for column: Place_of_Creation
2025-04-17 09:49:59 [ERROR]: Copied 335 values for column: People
2025-04-17 09:49:59 [ERROR]: Copied 335 values for column: Places
2025-04-17 09:49:59 [ERROR]: Copied 335 values for column: Summary
2025-04-17 09:49:59 [ERROR]: Copied 335 values for column: Creation_Place
2025-04-17 09:49:59 [ERROR]: Single author specified: Angus Bethune
2025-04-17 09:49:59 [ERROR]: Citation specified: HBCA, B194-A-2
2025-04-17 09:49:59 [ERROR]: Starting date and place analysis sequence using preset: Sequence_Diary
2025-04-17 09:49:59 [ERROR]: Using required headers from sequential preset: ['Date', 'Place', 'Author']
2025-04-17 09:49:59 [ERROR]: Clearing existing values for fresh date analysis
2025-04-17 09:49:59 [ERROR]: Copied existing Date values from compiled_df to date_df
2025-04-17 09:49:59 [ERROR]: Copied existing Author values from compiled_df to date_df
2025-04-17 09:49:59 [ERROR]: Added legacy Creation_Place column to date_df
2025-04-17 09:49:59 [ERROR]: Created date analysis dataframe with 335 rows and columns: ['Page', 'Text', 'Date', 'Place', 'Author', 'Creation_Place']
2025-04-17 09:49:59 [ERROR]: Using specified sequential preset: Sequence_Diary
2025-04-17 09:49:59 [ERROR]: Found required headers in sequence preset: ['Date', 'Place', 'Author']
2025-04-17 09:49:59 [ERROR]: Setting active sequential preset to: Sequence_Diary
2025-04-17 09:50:09 [ERROR]: Date analysis result dataframe has columns: ['Page', 'Text', 'Date', 'Place', 'Author', 'Creation_Place']
2025-04-17 09:50:09 [ERROR]: Date analysis result dataframe has 335 rows
2025-04-17 09:50:09 [ERROR]: Date analysis found 0 dates
2025-04-17 09:50:09 [ERROR]: Date analysis found 0 Date values
2025-04-17 09:50:09 [ERROR]: Date analysis found 0 Place values
2025-04-17 09:50:09 [ERROR]: Date analysis found 0 Author values
2025-04-17 09:50:09 [ERROR]: Sample row 0: {'Page': 0, 'Text': '1826/05/01 Monday: Raining throughout the mechanics were working at the Bridge'}
2025-04-17 09:50:09 [ERROR]: Sample row 1: {'Page': 1, 'Text': '1826/05/02 Tuesday: Rainy weather the mechanics were at the same Work. De Somme has been to day and yesterday removing Timber. I had the Scow which was sinking in the Creek Cleared of ice and water'}
2025-04-17 09:50:09 [ERROR]: Sample row 2: {'Page': 2, 'Text': '1826/05/03 Wednesday: Rainy weather in the forenoon a fine evening. The mechanics were at the Bridge and also employed the scow of water which got into it last night.'}
2025-04-17 09:50:09 [ERROR]: Date analysis returned dataframe with columns: Page, Text, Date, Place, Author, Creation_Place
2025-04-17 09:50:09 [ERROR]: Sample row 0: {'Page': 0, 'Text': '1826/05/01 Monday: Raining throughout the mechanics were working at the Bridge', 'Date': '', 'Place': '', 'Author': '', 'Creation_Place': ''}
2025-04-17 09:50:09 [ERROR]: Sample row 1: {'Page': 1, 'Text': '1826/05/02 Tuesday: Rainy weather the mechanics were at the same Work. De Somme has been to day and yesterday removing Timber. I had the Scow which was sinking in the Creek Cleared of ice and water', 'Date': '', 'Place': '', 'Author': '', 'Creation_Place': ''}
2025-04-17 09:50:09 [ERROR]: Sample row 2: {'Page': 2, 'Text': '1826/05/03 Wednesday: Rainy weather in the forenoon a fine evening. The mechanics were at the Bridge and also employed the scow of water which got into it last night.', 'Date': '', 'Place': '', 'Author': '', 'Creation_Place': ''}
2025-04-17 09:50:09 [ERROR]: Date and place analysis failed: invalid command name ".!toplevel10.!label"
Stack trace:
Traceback (most recent call last):
  File "d:\TranscriptionPearl\TranscriptionPearl\util\ExportFunctions.py", line 846, in _analyze_dates_sequentially
    progress_label.config(text="Finalizing date and place analysis...")
  File "C:\Users\mark_\anaconda3\envs\DocExtractor\Lib\tkinter\__init__.py", line 1702, in configure
    return self._configure('configure', cnf, kw)
           ^^^^^^^^^^^^^^^^^^^^^^^^^^^^^^^^^^^^^
  File "C:\Users\mark_\anaconda3\envs\DocExtractor\Lib\tkinter\__init__.py", line 1692, in _configure
    self.tk.call(_flatten((self._w, cmd)) + self._options(cnf))
_tkinter.TclError: invalid command name ".!toplevel10.!label"
2025-04-17 09:50:11 [ERROR]: Sequential preset headers: ['Date', 'Place', 'Author']
2025-04-17 09:50:11 [ERROR]: Preparing export dataframe. Text source: Original_Text
2025-04-17 09:50:11 [ERROR]: Using column 'Original_Text' for text
2025-04-17 09:50:11 [ERROR]: Overriding 'Author' column with single author: Angus Bethune
2025-04-17 09:50:11 [ERROR]: Metadata headers from preset 'Standard Metadata': ['Document_Type', 'Author', 'Correspondent', 'Correspondent_Place', 'Date', 'Place_of_Creation', 'People', 'Places', 'Summary']
2025-04-17 09:50:11 [ERROR]: Adding/overwriting with sequential headers: ['Date', 'Place', 'Author']
2025-04-17 09:50:11 [ERROR]: Sequential header 'Place' not found in compiled data.
2025-04-17 09:50:11 [ERROR]: Adding 'Citation' column.
2025-04-17 09:50:11 [ERROR]: Final ordered columns for export: ['Page', 'Author', 'Document_Type', 'Correspondent', 'Correspondent_Place', 'Date', 'Place_of_Creation', 'People', 'Places', 'Summary', 'Original_Text', 'Citation']
2025-04-17 09:50:24 [ERROR]: Failed to export text: '_tkinter.tkapp' object has no attribute 'find_right_text'
Stack trace:
Traceback (most recent call last):
  File "d:\TranscriptionPearl\TranscriptionPearl\util\ExportFunctions.py", line 47, in export
    text = self.app.find_right_text(index)
           ^^^^^^^^^^^^^^^^^^^^^^^^
  File "C:\Users\mark_\anaconda3\envs\DocExtractor\Lib\tkinter\__init__.py", line 2411, in __getattr__
    return getattr(self.tk, attr)
           ^^^^^^^^^^^^^^^^^^^^^^
AttributeError: '_tkinter.tkapp' object has no attribute 'find_right_text'
2025-04-17 09:51:23 [ERROR]: Failed to export text: '_tkinter.tkapp' object has no attribute 'find_right_text'
Stack trace:
Traceback (most recent call last):
  File "d:\TranscriptionPearl\TranscriptionPearl\util\ExportFunctions.py", line 47, in export
    text = self.app.find_right_text(index)
           ^^^^^^^^^^^^^^^^^^^^^^^^
  File "C:\Users\mark_\anaconda3\envs\DocExtractor\Lib\tkinter\__init__.py", line 2411, in __getattr__
    return getattr(self.tk, attr)
           ^^^^^^^^^^^^^^^^^^^^^^
AttributeError: '_tkinter.tkapp' object has no attribute 'find_right_text'
2025-04-18 09:13:17 [ERROR]: Enabled Names highlighting due to existing People data
2025-04-18 09:26:47 [ERROR]: Enabled Names highlighting due to existing People data
2025-04-18 09:45:17 [ERROR]: Enabled Names highlighting due to existing People data
2025-04-18 09:49:09 [ERROR]: Enabled Names highlighting due to existing People data
2025-04-18 09:53:33 [ERROR]: Enabled Names highlighting due to existing People data
2025-04-18 12:43:52 [ERROR]: Enabled Names highlighting due to existing People data
2025-04-18 12:45:36 [ERROR]: Enabled Names highlighting due to existing People data
2025-04-18 12:50:53 [ERROR]: Enabled Names highlighting due to existing People data
2025-04-18 13:07:22 [ERROR]: Enabled Names highlighting due to existing People data
2025-04-18 13:07:22 [ERROR]: Enabled Places highlighting due to existing Places data
2025-04-18 13:11:53 [ERROR]: Enabled Names highlighting due to existing People data
2025-04-18 13:11:53 [ERROR]: Enabled Places highlighting due to existing Places data
2025-04-18 13:16:54 [ERROR]: Enabled Names highlighting due to existing People data
2025-04-18 13:16:54 [ERROR]: Enabled Places highlighting due to existing Places data
2025-04-18 13:29:48 [ERROR]: Enabled Names highlighting due to existing People data
2025-04-18 13:29:48 [ERROR]: Enabled Places highlighting due to existing Places data
2025-04-18 21:37:23 [ERROR]: Enabled Names highlighting due to existing People data
2025-04-18 21:37:23 [ERROR]: Enabled Places highlighting due to existing Places data
2025-04-18 21:37:37 [ERROR]: Resolved 'Current Display' to actual column: Original_Text
2025-04-18 21:37:40 [ERROR]: Starting CSV export process
2025-04-18 21:37:40 [ERROR]: Ensuring these columns exist in the DataFrame: ['Page', 'Text', 'Citation', 'Document_Type', 'Author', 'Correspondent', 'Correspondent_Place', 'Date', 'Place_of_Creation', 'People', 'Places', 'Summary', 'People', 'Places', 'Translation', 'Separated_Text', 'Creation_Place', 'Date']
2025-04-18 21:37:40 [ERROR]: Added missing column: Text
2025-04-18 21:37:40 [ERROR]: Added missing column: Place_of_Creation
2025-04-18 21:37:40 [ERROR]: Using resolved text source column: Original_Text
2025-04-18 21:37:40 [ERROR]: Reset index for temp_df. New length: 31
2025-04-18 21:37:50 [ERROR]: Restored original index to updated_df for alignment.
2025-04-18 21:37:50 [ERROR]: Using metadata headers from preset 'Standard Metadata': Document Type;Author;Correspondent;Correspondent Place;Date;Place of Creation;People;Places;Summary
2025-04-18 21:37:50 [ERROR]: Added essential column: Creation_Place
2025-04-18 21:37:50 [ERROR]: Metadata columns to copy: ['Document_Type', 'Author', 'Correspondent', 'Correspondent_Place', 'Date', 'Place_of_Creation', 'People', 'Places', 'Summary', 'Creation_Place']
2025-04-18 21:37:50 [ERROR]: Copied 31 values for column: Document_Type
2025-04-18 21:37:50 [ERROR]: Copied 31 values for column: Author
2025-04-18 21:37:50 [ERROR]: Copied 31 values for column: Correspondent
2025-04-18 21:37:50 [ERROR]: Copied 31 values for column: Correspondent_Place
2025-04-18 21:37:50 [ERROR]: Copied 31 values for column: Date
2025-04-18 21:37:50 [ERROR]: Copied 31 values for column: Place_of_Creation
2025-04-18 21:37:50 [ERROR]: Copied 31 values for column: People
2025-04-18 21:37:50 [ERROR]: Copied 31 values for column: Places
2025-04-18 21:37:50 [ERROR]: Copied 31 values for column: Summary
2025-04-18 21:37:50 [ERROR]: Copied 31 values for column: Creation_Place
2025-04-18 21:37:54 [ERROR]: Failed to parse sequential API response: Expecting value: line 1 column 1 (char 0)
Response was: Error
Stack trace:
Traceback (most recent call last):
  File "c:\Programs\TranscriptionPearl\util\ExportFunctions.py", line 797, in _analyze_sequential_data
    parsed = json.loads(response)
  File "C:\Users\mark_\miniconda3\envs\PearlBot\Lib\json\__init__.py", line 346, in loads
    return _default_decoder.decode(s)
           ~~~~~~~~~~~~~~~~~~~~~~~^^^
  File "C:\Users\mark_\miniconda3\envs\PearlBot\Lib\json\decoder.py", line 344, in decode
    obj, end = self.raw_decode(s, idx=_w(s, 0).end())
               ~~~~~~~~~~~~~~~^^^^^^^^^^^^^^^^^^^^^^^
  File "C:\Users\mark_\miniconda3\envs\PearlBot\Lib\json\decoder.py", line 362, in raw_decode
    raise JSONDecodeError("Expecting value", s, err.value) from None
json.decoder.JSONDecodeError: Expecting value: line 1 column 1 (char 0)
2025-04-18 21:37:54 [ERROR]: Sequential preset headers: ['Place_Note']
2025-04-18 21:37:54 [ERROR]: Preparing export dataframe. Text source: Original_Text
2025-04-18 21:37:54 [ERROR]: Using column 'Original_Text' for text
2025-04-18 21:37:54 [ERROR]: Metadata headers from preset 'Standard Metadata': ['Document_Type', 'Author', 'Correspondent', 'Correspondent_Place', 'Date', 'Place_of_Creation', 'People', 'Places', 'Summary']
2025-04-18 21:37:54 [ERROR]: Adding/overwriting with sequential headers: ['Place_Note']
2025-04-18 21:37:54 [ERROR]: Sequential header 'Place_Note' not found in compiled data.
2025-04-18 21:37:54 [ERROR]: Final ordered columns for export: ['Page', 'Author', 'Document_Type', 'Correspondent', 'Correspondent_Place', 'Date', 'Place_of_Creation', 'People', 'Places', 'Summary', 'Original_Text']
2025-04-18 21:39:42 [ERROR]: Enabled Names highlighting due to existing People data
2025-04-18 21:39:42 [ERROR]: Enabled Places highlighting due to existing Places data
2025-04-18 21:39:53 [ERROR]: Resolved 'Current Display' to actual column: Original_Text
2025-04-18 21:40:00 [ERROR]: Starting CSV export process
2025-04-18 21:40:00 [ERROR]: Ensuring these columns exist in the DataFrame: ['Page', 'Text', 'Citation', 'Document_Type', 'Author', 'Correspondent', 'Correspondent_Place', 'Date', 'Place_of_Creation', 'People', 'Places', 'Summary', 'People', 'Places', 'Translation', 'Separated_Text', 'Creation_Place', 'Date']
2025-04-18 21:40:00 [ERROR]: Added missing column: Text
2025-04-18 21:40:00 [ERROR]: Added missing column: Place_of_Creation
2025-04-18 21:40:00 [ERROR]: Using resolved text source column: Original_Text
2025-04-18 21:40:00 [ERROR]: Reset index for temp_df. New length: 31
2025-04-18 21:40:08 [ERROR]: Restored original index to updated_df for alignment.
2025-04-18 21:40:08 [ERROR]: Using metadata headers from preset 'Standard Metadata': Document Type;Author;Correspondent;Correspondent Place;Date;Place of Creation;People;Places;Summary
2025-04-18 21:40:08 [ERROR]: Added essential column: Creation_Place
2025-04-18 21:40:08 [ERROR]: Metadata columns to copy: ['Document_Type', 'Author', 'Correspondent', 'Correspondent_Place', 'Date', 'Place_of_Creation', 'People', 'Places', 'Summary', 'Creation_Place']
2025-04-18 21:40:08 [ERROR]: Copied 31 values for column: Document_Type
2025-04-18 21:40:08 [ERROR]: Copied 31 values for column: Author
2025-04-18 21:40:08 [ERROR]: Copied 31 values for column: Correspondent
2025-04-18 21:40:08 [ERROR]: Copied 31 values for column: Correspondent_Place
2025-04-18 21:40:08 [ERROR]: Copied 31 values for column: Date
2025-04-18 21:40:08 [ERROR]: Copied 31 values for column: Place_of_Creation
2025-04-18 21:40:08 [ERROR]: Copied 31 values for column: People
2025-04-18 21:40:08 [ERROR]: Copied 31 values for column: Places
2025-04-18 21:40:08 [ERROR]: Copied 31 values for column: Summary
2025-04-18 21:40:08 [ERROR]: Copied 31 values for column: Creation_Place
2025-04-18 21:40:12 [ERROR]: Failed to parse sequential API response: Expecting value: line 1 column 1 (char 0)
Response was: Error
Stack trace:
Traceback (most recent call last):
  File "c:\Programs\TranscriptionPearl\util\ExportFunctions.py", line 797, in _analyze_sequential_data
    parsed = json.loads(response)
  File "C:\Users\mark_\miniconda3\envs\PearlBot\Lib\json\__init__.py", line 346, in loads
    return _default_decoder.decode(s)
           ~~~~~~~~~~~~~~~~~~~~~~~^^^
  File "C:\Users\mark_\miniconda3\envs\PearlBot\Lib\json\decoder.py", line 344, in decode
    obj, end = self.raw_decode(s, idx=_w(s, 0).end())
               ~~~~~~~~~~~~~~~^^^^^^^^^^^^^^^^^^^^^^^
  File "C:\Users\mark_\miniconda3\envs\PearlBot\Lib\json\decoder.py", line 362, in raw_decode
    raise JSONDecodeError("Expecting value", s, err.value) from None
json.decoder.JSONDecodeError: Expecting value: line 1 column 1 (char 0)
2025-04-18 21:40:12 [ERROR]: Sequential preset headers: ['Place_Note']
2025-04-18 21:40:12 [ERROR]: Preparing export dataframe. Text source: Original_Text
2025-04-18 21:40:12 [ERROR]: Using column 'Original_Text' for text
2025-04-18 21:40:12 [ERROR]: Metadata headers from preset 'Standard Metadata': ['Document_Type', 'Author', 'Correspondent', 'Correspondent_Place', 'Date', 'Place_of_Creation', 'People', 'Places', 'Summary']
2025-04-18 21:40:12 [ERROR]: Adding/overwriting with sequential headers: ['Place_Note']
2025-04-18 21:40:12 [ERROR]: Sequential header 'Place_Note' not found in compiled data.
2025-04-18 21:40:12 [ERROR]: Final ordered columns for export: ['Page', 'Author', 'Document_Type', 'Correspondent', 'Correspondent_Place', 'Date', 'Place_of_Creation', 'People', 'Places', 'Summary', 'Original_Text']
2025-04-18 21:40:35 [ERROR]: Enabled Names highlighting due to existing People data
2025-04-18 21:40:35 [ERROR]: Enabled Places highlighting due to existing Places data
2025-04-18 21:43:20 [ERROR]: Enabled Names highlighting due to existing People data
2025-04-18 21:43:20 [ERROR]: Enabled Places highlighting due to existing Places data
2025-04-18 21:43:29 [ERROR]: Resolved 'Current Display' to actual column: Original_Text
2025-04-18 21:43:33 [ERROR]: Starting CSV export process
2025-04-18 21:43:33 [ERROR]: Ensuring these columns exist in the DataFrame: ['Page', 'Text', 'Citation', 'Document_Type', 'Author', 'Correspondent', 'Correspondent_Place', 'Date', 'Place_of_Creation', 'People', 'Places', 'Summary', 'People', 'Places', 'Translation', 'Separated_Text', 'Creation_Place', 'Date']
2025-04-18 21:43:33 [ERROR]: Added missing column: Place_of_Creation
2025-04-18 21:43:33 [ERROR]: Added missing column: Text
2025-04-18 21:43:33 [ERROR]: Using resolved text source column: Original_Text
2025-04-18 21:43:33 [ERROR]: Reset index for temp_df. New length: 31
2025-04-18 21:43:41 [ERROR]: Restored original index to updated_df for alignment.
2025-04-18 21:43:41 [ERROR]: Using metadata headers from preset 'Standard Metadata': Document Type;Author;Correspondent;Correspondent Place;Date;Place of Creation;People;Places;Summary
2025-04-18 21:43:41 [ERROR]: Added essential column: Creation_Place
2025-04-18 21:43:41 [ERROR]: Metadata columns to copy: ['Document_Type', 'Author', 'Correspondent', 'Correspondent_Place', 'Date', 'Place_of_Creation', 'People', 'Places', 'Summary', 'Creation_Place']
2025-04-18 21:43:41 [ERROR]: Copied 31 values for column: Document_Type
2025-04-18 21:43:41 [ERROR]: Copied 31 values for column: Author
2025-04-18 21:43:41 [ERROR]: Copied 31 values for column: Correspondent
2025-04-18 21:43:41 [ERROR]: Copied 31 values for column: Correspondent_Place
2025-04-18 21:43:41 [ERROR]: Copied 31 values for column: Date
2025-04-18 21:43:41 [ERROR]: Copied 31 values for column: Place_of_Creation
2025-04-18 21:43:41 [ERROR]: Copied 31 values for column: People
2025-04-18 21:43:41 [ERROR]: Copied 31 values for column: Places
2025-04-18 21:43:41 [ERROR]: Copied 31 values for column: Summary
2025-04-18 21:43:41 [ERROR]: Copied 31 values for column: Creation_Place
2025-04-18 21:43:45 [ERROR]: Failed to parse sequential API response: Expecting value: line 1 column 1 (char 0)
Response was: Error
Stack trace:
Traceback (most recent call last):
  File "c:\Programs\TranscriptionPearl\util\ExportFunctions.py", line 797, in _analyze_sequential_data
    parsed = json.loads(response)
  File "C:\Users\mark_\miniconda3\envs\PearlBot\Lib\json\__init__.py", line 346, in loads
    return _default_decoder.decode(s)
           ~~~~~~~~~~~~~~~~~~~~~~~^^^
  File "C:\Users\mark_\miniconda3\envs\PearlBot\Lib\json\decoder.py", line 344, in decode
    obj, end = self.raw_decode(s, idx=_w(s, 0).end())
               ~~~~~~~~~~~~~~~^^^^^^^^^^^^^^^^^^^^^^^
  File "C:\Users\mark_\miniconda3\envs\PearlBot\Lib\json\decoder.py", line 362, in raw_decode
    raise JSONDecodeError("Expecting value", s, err.value) from None
json.decoder.JSONDecodeError: Expecting value: line 1 column 1 (char 0)
2025-04-18 21:43:45 [ERROR]: Sequential preset headers: ['Place_Note']
2025-04-18 21:43:45 [ERROR]: Preparing export dataframe. Text source: Original_Text
2025-04-18 21:43:45 [ERROR]: Using column 'Original_Text' for text
2025-04-18 21:43:45 [ERROR]: Metadata headers from preset 'Standard Metadata': ['Document_Type', 'Author', 'Correspondent', 'Correspondent_Place', 'Date', 'Place_of_Creation', 'People', 'Places', 'Summary']
2025-04-18 21:43:45 [ERROR]: Adding/overwriting with sequential headers: ['Place_Note']
2025-04-18 21:43:45 [ERROR]: Sequential header 'Place_Note' not found in compiled data.
2025-04-18 21:43:45 [ERROR]: Final ordered columns for export: ['Page', 'Author', 'Document_Type', 'Correspondent', 'Correspondent_Place', 'Date', 'Place_of_Creation', 'People', 'Places', 'Summary', 'Original_Text']
2025-04-18 21:45:24 [ERROR]: Resolved 'Current Display' to actual column: Original_Text
2025-04-18 21:45:27 [ERROR]: Starting CSV export process
2025-04-18 21:45:27 [ERROR]: Ensuring these columns exist in the DataFrame: ['Page', 'Text', 'Citation', 'Document_Type', 'Author', 'Correspondent', 'Correspondent_Place', 'Date', 'Place_of_Creation', 'People', 'Places', 'Summary', 'People', 'Places', 'Translation', 'Separated_Text', 'Creation_Place', 'Date']
2025-04-18 21:45:27 [ERROR]: Added missing column: Place_of_Creation
2025-04-18 21:45:27 [ERROR]: Added missing column: Text
2025-04-18 21:45:27 [ERROR]: Using resolved text source column: Original_Text
2025-04-18 21:45:27 [ERROR]: Reset index for temp_df. New length: 31
2025-04-18 21:45:37 [ERROR]: Restored original index to updated_df for alignment.
2025-04-18 21:45:37 [ERROR]: Using metadata headers from preset 'Standard Metadata': Document Type;Author;Correspondent;Correspondent Place;Date;Place of Creation;People;Places;Summary
2025-04-18 21:45:37 [ERROR]: Added essential column: Creation_Place
2025-04-18 21:45:37 [ERROR]: Metadata columns to copy: ['Document_Type', 'Author', 'Correspondent', 'Correspondent_Place', 'Date', 'Place_of_Creation', 'People', 'Places', 'Summary', 'Creation_Place']
2025-04-18 21:45:37 [ERROR]: Copied 31 values for column: Document_Type
2025-04-18 21:45:37 [ERROR]: Copied 31 values for column: Author
2025-04-18 21:45:37 [ERROR]: Copied 31 values for column: Correspondent
2025-04-18 21:45:37 [ERROR]: Copied 31 values for column: Correspondent_Place
2025-04-18 21:45:37 [ERROR]: Copied 31 values for column: Date
2025-04-18 21:45:37 [ERROR]: Copied 31 values for column: Place_of_Creation
2025-04-18 21:45:37 [ERROR]: Copied 31 values for column: People
2025-04-18 21:45:37 [ERROR]: Copied 31 values for column: Places
2025-04-18 21:45:37 [ERROR]: Copied 31 values for column: Summary
2025-04-18 21:45:37 [ERROR]: Copied 31 values for column: Creation_Place
2025-04-18 21:45:53 [ERROR]: Failed to parse sequential API response: Expecting value: line 1 column 1 (char 0)
Response was: ```json
[
  {
    "index": 0,
    "Place_Note": "Sault St Marys"
  },
  {
    "index": 1,
    "Place_Note": "Sault St Marys"
  },
  {
    "index": 2,
    "Place_Note": "Sault St Marys"
  },
  {
    "index": 3,
    "Place_Note": "Sault St Marys"
  },
  {
    "index": 4,
    "Place_Note": "Sault St Marys"
  },
  {
    "index": 5,
    "Place_Note": "Sault St Marys"
  },
  {
    "index": 6,
    "Place_Note": "Sault St Marys"
  },
  {
    "index": 7,
    "Place_Note": "Sault St Marys"
  },
  {
    "index": 8,
    "Place_Note": "Sault St Marys"
  },
  {
    "index": 9,
    "Place_Note": "Sault St Marys"
  },
  {
    "index": 10,
    "Place_Note": "Sault St Marys"
  },
  {
    "index": 11,
    "Place_Note": "Sault St Marys"
  },
  {
    "index": 12,
    "Place_Note": "Sault St Marys"
  },
  {
    "index": 13,
    "Place_Note": "Sault St Marys"
  },
  {
    "index": 14,
    "Place_Note": "Sault St Marys"
  },
  {
    "index": 15,
    "Place_Note": "Sault St Marys"
  },
  {
    "index": 16,
    "Place_Note": "Sault St Marys"
  },
  {
    "index": 17,
    "Place_Note": "Sault St Marys"
  },
  {
    "index": 18,
    "Place_Note": "Sault St Marys"
  },
  {
    "index": 19,
    "Place_Note": "Sault St Marys"
  },
  {
    "index": 20,
    "Place_Note": "Sault St Marys"
  },
  {
    "index": 21,
    "Place_Note": "Sault St Marys"
  },
  {
    "index": 22,
    "Place_Note": "Sault St Marys"
  },
  {
    "index": 23,
    "Place_Note": "Sault St Marys"
  },
  {
    "index": 24,
    "Place_Note": "Sault St Marys"
  },
  {
    "index": 25,
    "Place_Note": "Sault St Marys"
  },
  {
    "index": 26,
    "Place_Note": "Sault St Marys"
  },
  {
    "index": 27,
    "Place_Note": "Sault St Marys"
  },
  {
    "index": 28,
    "Place_Note": "Sault St Marys"
  },
  {
    "index": 29,
    "Place_Note": "Sault St Marys"
  },
  {
    "index": 30,
    "Place_Note": "Sault St Marys"
  }
]
```
Stack trace:
Traceback (most recent call last):
  File "c:\Programs\TranscriptionPearl\util\ExportFunctions.py", line 797, in _analyze_sequential_data
    parsed = json.loads(response)
  File "C:\Users\mark_\miniconda3\envs\PearlBot\Lib\json\__init__.py", line 346, in loads
    return _default_decoder.decode(s)
           ~~~~~~~~~~~~~~~~~~~~~~~^^^
  File "C:\Users\mark_\miniconda3\envs\PearlBot\Lib\json\decoder.py", line 344, in decode
    obj, end = self.raw_decode(s, idx=_w(s, 0).end())
               ~~~~~~~~~~~~~~~^^^^^^^^^^^^^^^^^^^^^^^
  File "C:\Users\mark_\miniconda3\envs\PearlBot\Lib\json\decoder.py", line 362, in raw_decode
    raise JSONDecodeError("Expecting value", s, err.value) from None
json.decoder.JSONDecodeError: Expecting value: line 1 column 1 (char 0)
2025-04-18 21:45:53 [ERROR]: Sequential preset headers: ['Place_Note']
2025-04-18 21:45:53 [ERROR]: Preparing export dataframe. Text source: Original_Text
2025-04-18 21:45:53 [ERROR]: Using column 'Original_Text' for text
2025-04-18 21:45:53 [ERROR]: Metadata headers from preset 'Standard Metadata': ['Document_Type', 'Author', 'Correspondent', 'Correspondent_Place', 'Date', 'Place_of_Creation', 'People', 'Places', 'Summary']
2025-04-18 21:45:53 [ERROR]: Adding/overwriting with sequential headers: ['Place_Note']
2025-04-18 21:45:53 [ERROR]: Sequential header 'Place_Note' not found in compiled data.
2025-04-18 21:45:53 [ERROR]: Final ordered columns for export: ['Page', 'Author', 'Document_Type', 'Correspondent', 'Correspondent_Place', 'Date', 'Place_of_Creation', 'People', 'Places', 'Summary', 'Original_Text']
2025-04-18 21:55:40 [ERROR]: Enabled Names highlighting due to existing People data
2025-04-18 21:55:40 [ERROR]: Enabled Places highlighting due to existing Places data
2025-04-18 21:55:51 [ERROR]: Resolved 'Current Display' to actual column: Original_Text
2025-04-18 21:55:54 [ERROR]: Starting CSV export process
2025-04-18 21:55:54 [ERROR]: Ensuring these columns exist in the DataFrame: ['Page', 'Text', 'Citation', 'Document_Type', 'Author', 'Correspondent', 'Correspondent_Place', 'Date', 'Place_of_Creation', 'People', 'Places', 'Summary', 'People', 'Places', 'Translation', 'Separated_Text', 'Creation_Place', 'Date']
2025-04-18 21:55:54 [ERROR]: Added missing column: Place_of_Creation
2025-04-18 21:55:54 [ERROR]: Added missing column: Text
2025-04-18 21:55:54 [ERROR]: Using resolved text source column: Original_Text
2025-04-18 21:55:54 [ERROR]: Reset index for temp_df. New length: 31
2025-04-18 21:56:02 [ERROR]: Restored original index to updated_df for alignment.
2025-04-18 21:56:02 [ERROR]: Using metadata headers from preset 'Standard Metadata': Document Type;Author;Correspondent;Correspondent Place;Date;Place of Creation;People;Places;Summary
2025-04-18 21:56:02 [ERROR]: Added essential column: Creation_Place
2025-04-18 21:56:02 [ERROR]: Metadata columns to copy: ['Document_Type', 'Author', 'Correspondent', 'Correspondent_Place', 'Date', 'Place_of_Creation', 'People', 'Places', 'Summary', 'Creation_Place']
2025-04-18 21:56:02 [ERROR]: Copied 31 values for column: Document_Type
2025-04-18 21:56:02 [ERROR]: Copied 31 values for column: Author
2025-04-18 21:56:02 [ERROR]: Copied 31 values for column: Correspondent
2025-04-18 21:56:02 [ERROR]: Copied 31 values for column: Correspondent_Place
2025-04-18 21:56:02 [ERROR]: Copied 31 values for column: Date
2025-04-18 21:56:02 [ERROR]: Copied 31 values for column: Place_of_Creation
2025-04-18 21:56:02 [ERROR]: Copied 31 values for column: People
2025-04-18 21:56:02 [ERROR]: Copied 31 values for column: Places
2025-04-18 21:56:02 [ERROR]: Copied 31 values for column: Summary
2025-04-18 21:56:02 [ERROR]: Copied 31 values for column: Creation_Place
2025-04-18 21:56:16 [ERROR]: Failed to parse sequential API response: Expecting value: line 1 column 1 (char 0)
Response was: ```json
[
  {"index": 0, "Place_Note": "Sault St Marys"},
  {"index": 1, "Place_Note": "Sault St Marys"},
  {"index": 2, "Place_Note": "Sault St Marys"},
  {"index": 3, "Place_Note": "Sault St Marys"},
  {"index": 4, "Place_Note": "Sault St Marys"},
  {"index": 5, "Place_Note": "Sault St Marys"},
  {"index": 6, "Place_Note": "Sault St Marys"},
  {"index": 7, "Place_Note": "Sault St Marys"},
  {"index": 8, "Place_Note": "Sault St Marys"},
  {"index": 9, "Place_Note": "Sault St Marys"},
  {"index": 10, "Place_Note": "Sault St Marys"},
  {"index": 11, "Place_Note": "Sault St Marys"},
  {"index": 12, "Place_Note": "Sault St Marys"},
  {"index": 13, "Place_Note": "Sault St Marys"},
  {"index": 14, "Place_Note": "Sault St Marys"},
  {"index": 15, "Place_Note": "Sault St Marys"},
  {"index": 16, "Place_Note": "Sault St Marys"},
  {"index": 17, "Place_Note": "Sault St Marys"},
  {"index": 18, "Place_Note": "Sault St Marys"},
  {"index": 19, "Place_Note": "Sault St Marys"},
  {"index": 20, "Place_Note": "Sault St Marys"},
  {"index": 21, "Place_Note": "Sault St Marys"},
  {"index": 22, "Place_Note": "Sault St Marys"},
  {"index": 23, "Place_Note": "Sault St Marys"},
  {"index": 24, "Place_Note": "Sault St Marys"},
  {"index": 25, "Place_Note": "Sault St Marys"},
  {"index": 26, "Place_Note": "Sault St Marys"},
  {"index": 27, "Place_Note": "Sault St Marys"},
  {"index": 28, "Place_Note": "Sault St Marys"},
  {"index": 29, "Place_Note": "Sault St Marys"},
  {"index": 30, "Place_Note": "Sault St Marys"}
]
```
Stack trace:
Traceback (most recent call last):
  File "c:\Programs\TranscriptionPearl\util\ExportFunctions.py", line 797, in _analyze_sequential_data
    parsed = json.loads(response)
  File "C:\Users\mark_\miniconda3\envs\PearlBot\Lib\json\__init__.py", line 346, in loads
    return _default_decoder.decode(s)
           ~~~~~~~~~~~~~~~~~~~~~~~^^^
  File "C:\Users\mark_\miniconda3\envs\PearlBot\Lib\json\decoder.py", line 344, in decode
    obj, end = self.raw_decode(s, idx=_w(s, 0).end())
               ~~~~~~~~~~~~~~~^^^^^^^^^^^^^^^^^^^^^^^
  File "C:\Users\mark_\miniconda3\envs\PearlBot\Lib\json\decoder.py", line 362, in raw_decode
    raise JSONDecodeError("Expecting value", s, err.value) from None
json.decoder.JSONDecodeError: Expecting value: line 1 column 1 (char 0)
2025-04-18 21:56:16 [ERROR]: Sequential preset headers: ['Place_Note']
2025-04-18 21:56:16 [ERROR]: Preparing export dataframe. Text source: Original_Text
2025-04-18 21:56:16 [ERROR]: Using column 'Original_Text' for text
2025-04-18 21:56:16 [ERROR]: Metadata headers from preset 'Standard Metadata': ['Document_Type', 'Author', 'Correspondent', 'Correspondent_Place', 'Date', 'Place_of_Creation', 'People', 'Places', 'Summary']
2025-04-18 21:56:16 [ERROR]: Adding/overwriting with sequential headers: ['Place_Note']
2025-04-18 21:56:16 [ERROR]: Sequential header 'Place_Note' not found in compiled data.
2025-04-18 21:56:16 [ERROR]: Final ordered columns for export: ['Page', 'Author', 'Document_Type', 'Correspondent', 'Correspondent_Place', 'Date', 'Place_of_Creation', 'People', 'Places', 'Summary', 'Original_Text']
2025-04-18 22:02:24 [ERROR]: Enabled Names highlighting due to existing People data
2025-04-18 22:02:24 [ERROR]: Enabled Places highlighting due to existing Places data
2025-04-18 22:02:34 [ERROR]: Resolved 'Current Display' to actual column: Original_Text
2025-04-18 22:02:37 [ERROR]: Starting CSV export process
2025-04-18 22:02:37 [ERROR]: Ensuring these columns exist in the DataFrame: ['Page', 'Text', 'Citation', 'Document_Type', 'Author', 'Correspondent', 'Correspondent_Place', 'Date', 'Place_of_Creation', 'People', 'Places', 'Summary', 'People', 'Places', 'Translation', 'Separated_Text', 'Creation_Place', 'Date']
2025-04-18 22:02:37 [ERROR]: Added missing column: Text
2025-04-18 22:02:37 [ERROR]: Added missing column: Place_of_Creation
2025-04-18 22:02:37 [ERROR]: Using resolved text source column: Original_Text
2025-04-18 22:02:37 [ERROR]: Reset index for temp_df. New length: 31
2025-04-18 22:02:46 [ERROR]: Restored original index to updated_df for alignment.
2025-04-18 22:02:46 [ERROR]: Using metadata headers from preset 'Standard Metadata': Document Type;Author;Correspondent;Correspondent Place;Date;Place of Creation;People;Places;Summary
2025-04-18 22:02:46 [ERROR]: Added essential column: Creation_Place
2025-04-18 22:02:46 [ERROR]: Metadata columns to copy: ['Document_Type', 'Author', 'Correspondent', 'Correspondent_Place', 'Date', 'Place_of_Creation', 'People', 'Places', 'Summary', 'Creation_Place']
2025-04-18 22:02:46 [ERROR]: Copied 31 values for column: Document_Type
2025-04-18 22:02:46 [ERROR]: Copied 31 values for column: Author
2025-04-18 22:02:46 [ERROR]: Copied 31 values for column: Correspondent
2025-04-18 22:02:46 [ERROR]: Copied 31 values for column: Correspondent_Place
2025-04-18 22:02:46 [ERROR]: Copied 31 values for column: Date
2025-04-18 22:02:46 [ERROR]: Copied 31 values for column: Place_of_Creation
2025-04-18 22:02:46 [ERROR]: Copied 31 values for column: People
2025-04-18 22:02:46 [ERROR]: Copied 31 values for column: Places
2025-04-18 22:02:46 [ERROR]: Copied 31 values for column: Summary
2025-04-18 22:02:46 [ERROR]: Copied 31 values for column: Creation_Place
2025-04-18 22:03:00 [ERROR]: Failed to parse sequential API response: Expecting value: line 1 column 1 (char 0)
Response was: ```json
[
  {"index": 0, "Place_Note": "Sault St Marys"},
  {"index": 1, "Place_Note": "Sault St Marys"},
  {"index": 2, "Place_Note": "Sault St Marys"},
  {"index": 3, "Place_Note": "Sault St Marys"},
  {"index": 4, "Place_Note": "Sault St Marys"},
  {"index": 5, "Place_Note": "Sault St Marys"},
  {"index": 6, "Place_Note": "Sault St Marys"},
  {"index": 7, "Place_Note": "Sault St Marys"},
  {"index": 8, "Place_Note": "Sault St Marys"},
  {"index": 9, "Place_Note": "Sault St Marys"},
  {"index": 10, "Place_Note": "Sault St Marys"},
  {"index": 11, "Place_Note": "Sault St Marys"},
  {"index": 12, "Place_Note": "Sault St Marys"},
  {"index": 13, "Place_Note": "Sault St Marys"},
  {"index": 14, "Place_Note": "Sault St Marys"},
  {"index": 15, "Place_Note": "Sault St Marys"},
  {"index": 16, "Place_Note": "Sault St Marys"},
  {"index": 17, "Place_Note": "Sault St Marys"},
  {"index": 18, "Place_Note": "Sault St Marys"},
  {"index": 19, "Place_Note": "Sault St Marys"},
  {"index": 20, "Place_Note": "Sault St Marys"},
  {"index": 21, "Place_Note": "Sault St Marys"},
  {"index": 22, "Place_Note": "Sault St Marys"},
  {"index": 23, "Place_Note": "Sault St Marys"},
  {"index": 24, "Place_Note": "Sault St Marys"},
  {"index": 25, "Place_Note": "Sault St Marys"},
  {"index": 26, "Place_Note": "Sault St Marys"},
  {"index": 27, "Place_Note": "Sault St Marys"},
  {"index": 28, "Place_Note": "Sault St Marys"},
  {"index": 29, "Place_Note": "Sault St Marys"},
  {"index": 30, "Place_Note": "Sault St Marys"}
]
```
Stack trace:
Traceback (most recent call last):
  File "c:\Programs\TranscriptionPearl\util\ExportFunctions.py", line 798, in _analyze_sequential_data
    json_results_to_df(response)
    ~~~~~~~~~~~~~~~~~~^^^^^^^^^^
  File "c:\Programs\TranscriptionPearl\util\SequentialData.py", line 76, in json_results_to_df
    data = json.loads(json_results)
  File "C:\Users\mark_\miniconda3\envs\PearlBot\Lib\json\__init__.py", line 346, in loads
    return _default_decoder.decode(s)
           ~~~~~~~~~~~~~~~~~~~~~~~^^^
  File "C:\Users\mark_\miniconda3\envs\PearlBot\Lib\json\decoder.py", line 344, in decode
    obj, end = self.raw_decode(s, idx=_w(s, 0).end())
               ~~~~~~~~~~~~~~~^^^^^^^^^^^^^^^^^^^^^^^
  File "C:\Users\mark_\miniconda3\envs\PearlBot\Lib\json\decoder.py", line 362, in raw_decode
    raise JSONDecodeError("Expecting value", s, err.value) from None
json.decoder.JSONDecodeError: Expecting value: line 1 column 1 (char 0)
2025-04-18 22:03:00 [ERROR]: Sequential preset headers: ['Place_Note']
2025-04-18 22:03:00 [ERROR]: Preparing export dataframe. Text source: Original_Text
2025-04-18 22:03:00 [ERROR]: Using column 'Original_Text' for text
2025-04-18 22:03:00 [ERROR]: Metadata headers from preset 'Standard Metadata': ['Document_Type', 'Author', 'Correspondent', 'Correspondent_Place', 'Date', 'Place_of_Creation', 'People', 'Places', 'Summary']
2025-04-18 22:03:00 [ERROR]: Adding/overwriting with sequential headers: ['Place_Note']
2025-04-18 22:03:00 [ERROR]: Sequential header 'Place_Note' not found in compiled data.
2025-04-18 22:03:00 [ERROR]: Final ordered columns for export: ['Page', 'Author', 'Document_Type', 'Correspondent', 'Correspondent_Place', 'Date', 'Place_of_Creation', 'People', 'Places', 'Summary', 'Original_Text']
2025-04-18 22:07:00 [ERROR]: Enabled Names highlighting due to existing People data
2025-04-18 22:07:00 [ERROR]: Enabled Places highlighting due to existing Places data
2025-04-18 22:07:09 [ERROR]: Resolved 'Current Display' to actual column: Original_Text
2025-04-18 22:07:12 [ERROR]: Starting CSV export process
2025-04-18 22:07:12 [ERROR]: Ensuring these columns exist in the DataFrame: ['Page', 'Text', 'Citation', 'Document_Type', 'Author', 'Correspondent', 'Correspondent_Place', 'Date', 'Place_of_Creation', 'People', 'Places', 'Summary', 'People', 'Places', 'Translation', 'Separated_Text', 'Creation_Place', 'Date']
2025-04-18 22:07:12 [ERROR]: Added missing column: Place_of_Creation
2025-04-18 22:07:12 [ERROR]: Added missing column: Text
2025-04-18 22:07:12 [ERROR]: Using resolved text source column: Original_Text
2025-04-18 22:07:12 [ERROR]: Reset index for temp_df. New length: 31
2025-04-18 22:07:20 [ERROR]: Restored original index to updated_df for alignment.
2025-04-18 22:07:20 [ERROR]: Using metadata headers from preset 'Standard Metadata': Document Type;Author;Correspondent;Correspondent Place;Date;Place of Creation;People;Places;Summary
2025-04-18 22:07:20 [ERROR]: Added essential column: Creation_Place
2025-04-18 22:07:20 [ERROR]: Metadata columns to copy: ['Document_Type', 'Author', 'Correspondent', 'Correspondent_Place', 'Date', 'Place_of_Creation', 'People', 'Places', 'Summary', 'Creation_Place']
2025-04-18 22:07:20 [ERROR]: Copied 31 values for column: Document_Type
2025-04-18 22:07:20 [ERROR]: Copied 31 values for column: Author
2025-04-18 22:07:20 [ERROR]: Copied 31 values for column: Correspondent
2025-04-18 22:07:20 [ERROR]: Copied 31 values for column: Correspondent_Place
2025-04-18 22:07:20 [ERROR]: Copied 31 values for column: Date
2025-04-18 22:07:20 [ERROR]: Copied 31 values for column: Place_of_Creation
2025-04-18 22:07:20 [ERROR]: Copied 31 values for column: People
2025-04-18 22:07:20 [ERROR]: Copied 31 values for column: Places
2025-04-18 22:07:20 [ERROR]: Copied 31 values for column: Summary
2025-04-18 22:07:20 [ERROR]: Copied 31 values for column: Creation_Place
2025-04-18 22:07:34 [ERROR]: Failed to parse sequential API response: Expecting value: line 1 column 1 (char 0)
Response was: ```json
[
  {
    "index": 0,
    "Place_Note": "Sault St Marys"
  },
  {
    "index": 1,
    "Place_Note": "Sault St Marys"
  },
  {
    "index": 2,
    "Place_Note": "Sault St Marys"
  },
  {
    "index": 3,
    "Place_Note": "Sault St Marys"
  },
  {
    "index": 4,
    "Place_Note": "Sault St Marys"
  },
  {
    "index": 5,
    "Place_Note": "Sault St Marys"
  },
  {
    "index": 6,
    "Place_Note": "Sault St Marys"
  },
  {
    "index": 7,
    "Place_Note": "Sault St Marys"
  },
  {
    "index": 8,
    "Place_Note": "Sault St Marys"
  },
  {
    "index": 9,
    "Place_Note": "Sault St Marys"
  },
  {
    "index": 10,
    "Place_Note": "Sault St Marys"
  },
  {
    "index": 11,
    "Place_Note": "Sault St Marys"
  },
  {
    "index": 12,
    "Place_Note": "Sault St Marys"
  },
  {
    "index": 13,
    "Place_Note": "Sault St Marys"
  },
  {
    "index": 14,
    "Place_Note": "Sault St Marys"
  },
  {
    "index": 15,
    "Place_Note": "Sault St Marys"
  },
  {
    "index": 16,
    "Place_Note": "Sault St Marys"
  },
  {
    "index": 17,
    "Place_Note": "Sault St Marys"
  },
  {
    "index": 18,
    "Place_Note": "Sault St Marys"
  },
  {
    "index": 19,
    "Place_Note": "Sault St Marys"
  },
  {
    "index": 20,
    "Place_Note": "Sault St Marys"
  },
  {
    "index": 21,
    "Place_Note": "Sault St Marys"
  },
  {
    "index": 22,
    "Place_Note": "Sault St Marys"
  },
  {
    "index": 23,
    "Place_Note": "Sault St Marys"
  },
  {
    "index": 24,
    "Place_Note": "Sault St Marys"
  },
  {
    "index": 25,
    "Place_Note": "Sault St Marys"
  },
  {
    "index": 26,
    "Place_Note": "Sault St Marys"
  },
  {
    "index": 27,
    "Place_Note": "Sault St Marys"
  },
  {
    "index": 28,
    "Place_Note": "Sault St Marys"
  },
  {
    "index": 29,
    "Place_Note": "Sault St Marys"
  },
  {
    "index": 30,
    "Place_Note": "Sault St Marys"
  }
]
```
Stack trace:
Traceback (most recent call last):
  File "c:\Programs\TranscriptionPearl\util\ExportFunctions.py", line 799, in _analyze_sequential_data
    parsed = json.loads(response)
  File "C:\Users\mark_\miniconda3\envs\PearlBot\Lib\json\__init__.py", line 346, in loads
    return _default_decoder.decode(s)
           ~~~~~~~~~~~~~~~~~~~~~~~^^^
  File "C:\Users\mark_\miniconda3\envs\PearlBot\Lib\json\decoder.py", line 344, in decode
    obj, end = self.raw_decode(s, idx=_w(s, 0).end())
               ~~~~~~~~~~~~~~~^^^^^^^^^^^^^^^^^^^^^^^
  File "C:\Users\mark_\miniconda3\envs\PearlBot\Lib\json\decoder.py", line 362, in raw_decode
    raise JSONDecodeError("Expecting value", s, err.value) from None
json.decoder.JSONDecodeError: Expecting value: line 1 column 1 (char 0)
2025-04-18 22:07:34 [ERROR]: Sequential preset headers: ['Place_Note']
2025-04-18 22:07:34 [ERROR]: Preparing export dataframe. Text source: Original_Text
2025-04-18 22:07:34 [ERROR]: Using column 'Original_Text' for text
2025-04-18 22:07:34 [ERROR]: Metadata headers from preset 'Standard Metadata': ['Document_Type', 'Author', 'Correspondent', 'Correspondent_Place', 'Date', 'Place_of_Creation', 'People', 'Places', 'Summary']
2025-04-18 22:07:34 [ERROR]: Adding/overwriting with sequential headers: ['Place_Note']
2025-04-18 22:07:34 [ERROR]: Sequential header 'Place_Note' not found in compiled data.
2025-04-18 22:07:34 [ERROR]: Final ordered columns for export: ['Page', 'Author', 'Document_Type', 'Correspondent', 'Correspondent_Place', 'Date', 'Place_of_Creation', 'People', 'Places', 'Summary', 'Original_Text']
2025-04-18 22:10:23 [ERROR]: Enabled Names highlighting due to existing People data
2025-04-18 22:10:23 [ERROR]: Enabled Places highlighting due to existing Places data
2025-04-18 22:10:34 [ERROR]: Resolved 'Current Display' to actual column: Original_Text
2025-04-18 22:10:37 [ERROR]: Starting CSV export process
2025-04-18 22:10:37 [ERROR]: Ensuring these columns exist in the DataFrame: ['Page', 'Text', 'Citation', 'Document_Type', 'Author', 'Correspondent', 'Correspondent_Place', 'Date', 'Place_of_Creation', 'People', 'Places', 'Summary', 'People', 'Places', 'Translation', 'Separated_Text', 'Creation_Place', 'Date']
2025-04-18 22:10:37 [ERROR]: Added missing column: Place_of_Creation
2025-04-18 22:10:37 [ERROR]: Added missing column: Text
2025-04-18 22:10:37 [ERROR]: Using resolved text source column: Original_Text
2025-04-18 22:10:37 [ERROR]: Reset index for temp_df. New length: 31
2025-04-18 22:10:45 [ERROR]: Restored original index to updated_df for alignment.
2025-04-18 22:10:45 [ERROR]: Using metadata headers from preset 'Standard Metadata': Document Type;Author;Correspondent;Correspondent Place;Date;Place of Creation;People;Places;Summary
2025-04-18 22:10:45 [ERROR]: Added essential column: Creation_Place
2025-04-18 22:10:45 [ERROR]: Metadata columns to copy: ['Document_Type', 'Author', 'Correspondent', 'Correspondent_Place', 'Date', 'Place_of_Creation', 'People', 'Places', 'Summary', 'Creation_Place']
2025-04-18 22:10:45 [ERROR]: Copied 31 values for column: Document_Type
2025-04-18 22:10:45 [ERROR]: Copied 31 values for column: Author
2025-04-18 22:10:45 [ERROR]: Copied 31 values for column: Correspondent
2025-04-18 22:10:45 [ERROR]: Copied 31 values for column: Correspondent_Place
2025-04-18 22:10:45 [ERROR]: Copied 31 values for column: Date
2025-04-18 22:10:45 [ERROR]: Copied 31 values for column: Place_of_Creation
2025-04-18 22:10:45 [ERROR]: Copied 31 values for column: People
2025-04-18 22:10:45 [ERROR]: Copied 31 values for column: Places
2025-04-18 22:10:45 [ERROR]: Copied 31 values for column: Summary
2025-04-18 22:10:45 [ERROR]: Copied 31 values for column: Creation_Place
2025-04-18 22:11:00 [ERROR]: Successfully merged sequential analysis results into DataFrame. New columns: ['Place_Note']
2025-04-18 22:11:00 [ERROR]: Sequential preset headers: ['Place_Note']
2025-04-18 22:11:00 [ERROR]: Preparing export dataframe. Text source: Original_Text
2025-04-18 22:11:00 [ERROR]: Using column 'Original_Text' for text
2025-04-18 22:11:00 [ERROR]: Final ordered columns for export: ['Page', 'Author', 'Date', 'Place_of_Creation', 'Original_Text', 'Citation', 'Corrected_Text', 'Correspondent', 'Correspondent_Place', 'Creation_Place', 'Data_Analysis', 'Document_No', 'Document_Type', 'Errors', 'Errors_Source', 'Formatted_Text', 'Image_Path', 'Index', 'Notes', 'People', 'Places', 'Query_Data', 'Query_Memory', 'Relevance', 'Separated_Text', 'Summary', 'Temp_Data_Analysis', 'Text_Path', 'Text_Toggle', 'Translation', 'Document_Page', 'Text', 'Place_Note']
2025-04-18 22:14:51 [ERROR]: Enabled Names highlighting due to existing People data
2025-04-18 22:14:51 [ERROR]: Enabled Places highlighting due to existing Places data
2025-04-18 22:15:00 [ERROR]: Resolved 'Current Display' to actual column: Original_Text
2025-04-18 22:15:04 [ERROR]: Starting CSV export process
2025-04-18 22:15:04 [ERROR]: Ensuring these columns exist in the DataFrame: ['Page', 'Text', 'Citation', 'Document_Type', 'Author', 'Correspondent', 'Correspondent_Place', 'Date', 'Place_of_Creation', 'People', 'Places', 'Summary', 'People', 'Places', 'Translation', 'Separated_Text', 'Creation_Place', 'Date']
2025-04-18 22:15:04 [ERROR]: Added missing column: Text
2025-04-18 22:15:04 [ERROR]: Added missing column: Place_of_Creation
2025-04-18 22:15:04 [ERROR]: Using resolved text source column: Original_Text
2025-04-18 22:15:04 [ERROR]: Reset index for temp_df. New length: 31
2025-04-18 22:15:14 [ERROR]: Restored original index to updated_df for alignment.
2025-04-18 22:15:14 [ERROR]: Using metadata headers from preset 'Standard Metadata': Document Type;Author;Correspondent;Correspondent Place;Date;Place of Creation;People;Places;Summary
2025-04-18 22:15:14 [ERROR]: Added essential column: Creation_Place
2025-04-18 22:15:14 [ERROR]: Metadata columns to copy: ['Document_Type', 'Author', 'Correspondent', 'Correspondent_Place', 'Date', 'Place_of_Creation', 'People', 'Places', 'Summary', 'Creation_Place']
2025-04-18 22:15:14 [ERROR]: Copied 31 values for column: Document_Type
2025-04-18 22:15:14 [ERROR]: Copied 31 values for column: Author
2025-04-18 22:15:14 [ERROR]: Copied 31 values for column: Correspondent
2025-04-18 22:15:14 [ERROR]: Copied 31 values for column: Correspondent_Place
2025-04-18 22:15:14 [ERROR]: Copied 31 values for column: Date
2025-04-18 22:15:14 [ERROR]: Copied 31 values for column: Place_of_Creation
2025-04-18 22:15:14 [ERROR]: Copied 31 values for column: People
2025-04-18 22:15:14 [ERROR]: Copied 31 values for column: Places
2025-04-18 22:15:14 [ERROR]: Copied 31 values for column: Summary
2025-04-18 22:15:14 [ERROR]: Copied 31 values for column: Creation_Place
2025-04-18 22:15:31 [ERROR]: Successfully merged sequential analysis results. New columns added: ['Place_Note']
2025-04-18 22:15:31 [ERROR]: Sequential preset headers: ['Place_Note']
2025-04-18 22:15:31 [ERROR]: Preparing export dataframe. Text source: Original_Text
2025-04-18 22:15:31 [ERROR]: Using column 'Original_Text' for text
2025-04-18 22:15:31 [ERROR]: Metadata headers from preset 'Standard Metadata': ['Document_Type', 'Author', 'Correspondent', 'Correspondent_Place', 'Date', 'Place_of_Creation', 'People', 'Places', 'Summary']
2025-04-18 22:15:31 [ERROR]: Adding sequential columns: ['Place_Note']
2025-04-18 22:15:31 [ERROR]: Final ordered columns for export: ['Page', 'Original_Text', 'Author', 'Citation', 'Document_Type', 'Correspondent', 'Correspondent_Place', 'Date', 'Place_of_Creation', 'People', 'Places', 'Summary', 'Place_Note', 'Corrected_Text', 'Creation_Place', 'Data_Analysis', 'Document_No', 'Errors', 'Errors_Source', 'Formatted_Text', 'Image_Path', 'Index', 'Notes', 'Query_Data', 'Query_Memory', 'Relevance', 'Separated_Text', 'Temp_Data_Analysis', 'Text_Path', 'Text_Toggle', 'Translation', 'Document_Page', 'Text']
2025-04-18 22:17:51 [ERROR]: Enabled Names highlighting due to existing People data
2025-04-18 22:17:51 [ERROR]: Enabled Places highlighting due to existing Places data
2025-04-18 22:18:03 [ERROR]: Resolved 'Current Display' to actual column: Original_Text
2025-04-18 22:18:07 [ERROR]: Starting CSV export process
2025-04-18 22:18:07 [ERROR]: Ensuring these columns exist in the DataFrame: ['Page', 'Text', 'Citation', 'Document_Type', 'Author', 'Correspondent', 'Correspondent_Place', 'Date', 'Place_of_Creation', 'People', 'Places', 'Summary', 'People', 'Places', 'Translation', 'Separated_Text', 'Creation_Place', 'Date']
2025-04-18 22:18:07 [ERROR]: Added missing column: Place_of_Creation
2025-04-18 22:18:07 [ERROR]: Added missing column: Text
2025-04-18 22:18:07 [ERROR]: Using resolved text source column: Original_Text
2025-04-18 22:18:07 [ERROR]: Reset index for temp_df. New length: 31
2025-04-18 22:18:17 [ERROR]: Restored original index to updated_df for alignment.
2025-04-18 22:18:17 [ERROR]: Using metadata headers from preset 'Standard Metadata': Document Type;Author;Correspondent;Correspondent Place;Date;Place of Creation;People;Places;Summary
2025-04-18 22:18:17 [ERROR]: Added essential column: Creation_Place
2025-04-18 22:18:17 [ERROR]: Metadata columns to copy: ['Document_Type', 'Author', 'Correspondent', 'Correspondent_Place', 'Date', 'Place_of_Creation', 'People', 'Places', 'Summary', 'Creation_Place']
2025-04-18 22:18:17 [ERROR]: Copied 31 values for column: Document_Type
2025-04-18 22:18:17 [ERROR]: Copied 31 values for column: Author
2025-04-18 22:18:17 [ERROR]: Copied 31 values for column: Correspondent
2025-04-18 22:18:17 [ERROR]: Copied 31 values for column: Correspondent_Place
2025-04-18 22:18:17 [ERROR]: Copied 31 values for column: Date
2025-04-18 22:18:17 [ERROR]: Copied 31 values for column: Place_of_Creation
2025-04-18 22:18:17 [ERROR]: Copied 31 values for column: People
2025-04-18 22:18:17 [ERROR]: Copied 31 values for column: Places
2025-04-18 22:18:17 [ERROR]: Copied 31 values for column: Summary
2025-04-18 22:18:17 [ERROR]: Copied 31 values for column: Creation_Place
2025-04-18 22:18:36 [ERROR]: Successfully merged sequential analysis results into DataFrame. New columns: ['Place_Note']
2025-04-18 22:18:36 [ERROR]: Sequential preset headers: ['Place_Note']
2025-04-18 22:18:36 [ERROR]: Preparing export dataframe. Text source: Original_Text
2025-04-18 22:18:36 [ERROR]: Using column 'Original_Text' for text
2025-04-18 22:18:36 [ERROR]: Final ordered columns for export: ['Page', 'Author', 'Date', 'Place_of_Creation', 'Original_Text', 'Citation', 'Corrected_Text', 'Correspondent', 'Correspondent_Place', 'Creation_Place', 'Data_Analysis', 'Document_No', 'Document_Type', 'Errors', 'Errors_Source', 'Formatted_Text', 'Image_Path', 'Index', 'Notes', 'People', 'Places', 'Query_Data', 'Query_Memory', 'Relevance', 'Separated_Text', 'Summary', 'Temp_Data_Analysis', 'Text_Path', 'Text_Toggle', 'Translation', 'Document_Page', 'Text', 'Place_Note']
2025-04-18 22:23:54 [ERROR]: Enabled Names highlighting due to existing People data
2025-04-18 22:23:54 [ERROR]: Enabled Places highlighting due to existing Places data
2025-04-18 22:24:04 [ERROR]: Resolved 'Current Display' to actual column: Original_Text
2025-04-18 22:24:07 [ERROR]: Starting CSV export process
2025-04-18 22:24:07 [ERROR]: Ensuring these columns exist in the DataFrame: ['Page', 'Text', 'Citation', 'Document_Type', 'Author', 'Correspondent', 'Correspondent_Place', 'Date', 'Place_of_Creation', 'People', 'Places', 'Summary', 'People', 'Places', 'Translation', 'Separated_Text', 'Creation_Place', 'Date']
2025-04-18 22:24:07 [ERROR]: Added missing column: Text
2025-04-18 22:24:07 [ERROR]: Added missing column: Place_of_Creation
2025-04-18 22:24:07 [ERROR]: Using resolved text source column: Original_Text
2025-04-18 22:24:07 [ERROR]: Reset index for temp_df. New length: 31
2025-04-18 22:24:18 [ERROR]: Restored original index to updated_df for alignment.
2025-04-18 22:24:18 [ERROR]: Using metadata headers from preset 'Standard Metadata': Document Type;Author;Correspondent;Correspondent Place;Date;Place of Creation;People;Places;Summary
2025-04-18 22:24:18 [ERROR]: Added essential column: Creation_Place
2025-04-18 22:24:18 [ERROR]: Metadata columns to copy: ['Document_Type', 'Author', 'Correspondent', 'Correspondent_Place', 'Date', 'Place_of_Creation', 'People', 'Places', 'Summary', 'Creation_Place']
2025-04-18 22:24:18 [ERROR]: Copied 31 values for column: Document_Type
2025-04-18 22:24:18 [ERROR]: Copied 31 values for column: Author
2025-04-18 22:24:18 [ERROR]: Copied 31 values for column: Correspondent
2025-04-18 22:24:18 [ERROR]: Copied 31 values for column: Correspondent_Place
2025-04-18 22:24:18 [ERROR]: Copied 31 values for column: Date
2025-04-18 22:24:18 [ERROR]: Copied 31 values for column: Place_of_Creation
2025-04-18 22:24:18 [ERROR]: Copied 31 values for column: People
2025-04-18 22:24:18 [ERROR]: Copied 31 values for column: Places
2025-04-18 22:24:18 [ERROR]: Copied 31 values for column: Summary
2025-04-18 22:24:18 [ERROR]: Copied 31 values for column: Creation_Place
2025-04-18 22:24:32 [ERROR]: Successfully merged sequential analysis results. New columns added: ['Place_Note']
2025-04-18 22:24:32 [ERROR]: Preparing export dataframe. Text source: Original_Text, New sequential cols: ['Place_Note']
2025-04-18 22:24:32 [ERROR]: Using column 'Original_Text' for text
2025-04-18 22:24:32 [ERROR]: Metadata headers from preset 'Standard Metadata': ['Document_Type', 'Author', 'Correspondent', 'Correspondent_Place', 'Date', 'Place_of_Creation', 'People', 'Places', 'Summary']
2025-04-18 22:24:32 [ERROR]: Final columns selected for export: ['Page', 'Original_Text', 'Document_Type', 'Author', 'Correspondent', 'Correspondent_Place', 'Date', 'Place_of_Creation', 'People', 'Places', 'Summary', 'Place_Note']
2025-04-18 22:33:58 [ERROR]: Enabled Names highlighting due to existing People data
2025-04-18 22:33:58 [ERROR]: Enabled Places highlighting due to existing Places data
2025-04-18 22:34:07 [ERROR]: Resolved 'Current Display' to actual column: Original_Text
2025-04-18 22:34:12 [ERROR]: Starting CSV export process
2025-04-18 22:34:12 [ERROR]: Ensuring these columns exist in the DataFrame: ['Page', 'Text', 'Citation', 'Document_Type', 'Author', 'Correspondent', 'Correspondent_Place', 'Date', 'Place_of_Creation', 'People', 'Places', 'Summary', 'People', 'Places', 'Translation', 'Separated_Text', 'Creation_Place', 'Date']
2025-04-18 22:34:12 [ERROR]: Added missing column: Text
2025-04-18 22:34:12 [ERROR]: Added missing column: Place_of_Creation
2025-04-18 22:34:12 [ERROR]: Using resolved text source column: Original_Text
2025-04-18 22:34:12 [ERROR]: Reset index for temp_df. New length: 31
2025-04-18 22:34:21 [ERROR]: Restored original index to updated_df for alignment.
2025-04-18 22:34:21 [ERROR]: Using metadata headers from preset 'Standard Metadata': Document Type;Author;Correspondent;Correspondent Place;Date;Place of Creation;People;Places;Summary
2025-04-18 22:34:21 [ERROR]: Added essential column: Creation_Place
2025-04-18 22:34:21 [ERROR]: Metadata columns to copy: ['Document_Type', 'Author', 'Correspondent', 'Correspondent_Place', 'Date', 'Place_of_Creation', 'People', 'Places', 'Summary', 'Creation_Place']
2025-04-18 22:34:21 [ERROR]: Copied 31 values for column: Document_Type
2025-04-18 22:34:21 [ERROR]: Copied 31 values for column: Author
2025-04-18 22:34:21 [ERROR]: Copied 31 values for column: Correspondent
2025-04-18 22:34:21 [ERROR]: Copied 31 values for column: Correspondent_Place
2025-04-18 22:34:21 [ERROR]: Copied 31 values for column: Date
2025-04-18 22:34:21 [ERROR]: Copied 31 values for column: Place_of_Creation
2025-04-18 22:34:21 [ERROR]: Copied 31 values for column: People
2025-04-18 22:34:21 [ERROR]: Copied 31 values for column: Places
2025-04-18 22:34:21 [ERROR]: Copied 31 values for column: Summary
2025-04-18 22:34:21 [ERROR]: Copied 31 values for column: Creation_Place
2025-04-18 22:34:34 [ERROR]: Successfully merged sequential analysis results. New columns added: ['Place_Note']
2025-04-18 22:34:34 [ERROR]: Preparing export dataframe. Text source: Original_Text, New sequential cols: ['Place_Note']
2025-04-18 22:34:34 [ERROR]: Using column 'Original_Text' for text
2025-04-18 22:34:34 [ERROR]: Metadata headers from preset 'Standard Metadata': ['Document_Type', 'Author', 'Correspondent', 'Correspondent_Place', 'Date', 'Place_of_Creation', 'People', 'Places', 'Summary']
2025-04-18 22:34:34 [ERROR]: Final columns selected for export after empty check: ['Page', 'Original_Text', 'Document_Type', 'Date', 'Place_of_Creation', 'People', 'Places', 'Summary', 'Place_Note']
2025-04-18 22:40:55 [ERROR]: Enabled Names highlighting due to existing People data
2025-04-18 22:40:55 [ERROR]: Enabled Places highlighting due to existing Places data
2025-04-18 22:41:04 [ERROR]: Resolved 'Current Display' to actual column: Original_Text
2025-04-18 22:41:07 [ERROR]: Starting CSV export process
2025-04-18 22:41:07 [ERROR]: Ensuring these columns exist in the DataFrame: ['Page', 'Text', 'Citation', 'Document_Type', 'Author', 'Correspondent', 'Correspondent_Place', 'Date', 'Place_of_Creation', 'People', 'Places', 'Summary', 'People', 'Places', 'Translation', 'Separated_Text', 'Creation_Place', 'Date']
2025-04-18 22:41:07 [ERROR]: Added missing column: Place_of_Creation
2025-04-18 22:41:07 [ERROR]: Added missing column: Text
2025-04-18 22:41:07 [ERROR]: Using resolved text source column: Original_Text
2025-04-18 22:41:07 [ERROR]: Reset index for temp_df. New length: 31
2025-04-18 22:41:18 [ERROR]: Restored original index to updated_df for alignment.
2025-04-18 22:41:18 [ERROR]: Using metadata headers from preset 'Standard Metadata': Document Type;Author;Correspondent;Correspondent Place;Date;Place of Creation;People;Places;Summary
2025-04-18 22:41:18 [ERROR]: Added essential column: Creation_Place
2025-04-18 22:41:18 [ERROR]: Metadata columns to copy: ['Document_Type', 'Author', 'Correspondent', 'Correspondent_Place', 'Date', 'Place_of_Creation', 'People', 'Places', 'Summary', 'Creation_Place']
2025-04-18 22:41:18 [ERROR]: Copied 31 values for column: Document_Type
2025-04-18 22:41:18 [ERROR]: Copied 31 values for column: Author
2025-04-18 22:41:18 [ERROR]: Copied 31 values for column: Correspondent
2025-04-18 22:41:18 [ERROR]: Copied 31 values for column: Correspondent_Place
2025-04-18 22:41:18 [ERROR]: Copied 31 values for column: Date
2025-04-18 22:41:18 [ERROR]: Copied 31 values for column: Place_of_Creation
2025-04-18 22:41:18 [ERROR]: Copied 31 values for column: People
2025-04-18 22:41:18 [ERROR]: Copied 31 values for column: Places
2025-04-18 22:41:18 [ERROR]: Copied 31 values for column: Summary
2025-04-18 22:41:18 [ERROR]: Copied 31 values for column: Creation_Place
2025-04-18 22:41:30 [ERROR]: Successfully merged sequential analysis results. New columns added: ['Place_Note']
2025-04-18 22:41:30 [ERROR]: Preparing export dataframe. Text source: Original_Text, New sequential cols: ['Place_Note']
2025-04-18 22:41:30 [ERROR]: Using column 'Original_Text' for text
2025-04-18 22:41:30 [ERROR]: Metadata headers from preset 'Standard Metadata': ['Document_Type', 'Author', 'Correspondent', 'Correspondent_Place', 'Date', 'Place_of_Creation', 'People', 'Places', 'Summary']
2025-04-18 22:41:30 [ERROR]: Final columns selected for export after empty check: ['Page', 'Original_Text', 'Document_Type', 'Date', 'Place_of_Creation', 'People', 'Places', 'Summary', 'Place_Note']
