2025-04-08 21:17:29 [ERROR]: Starting CSV export process
2025-04-08 21:17:29 [ERROR]: Ensuring these columns exist in the DataFrame: ['Page', 'Text', 'Citation', 'Document_Type', 'Author', 'Correspondent', 'Correspondent_Place', 'Date', 'Place_of_Creation', 'People', 'Places', 'Summary', 'People', 'Places', 'Translation', 'Separated_Text', 'Creation_Place', 'Date']
2025-04-08 21:17:29 [ERROR]: Added missing column: Place_of_Creation
2025-04-08 21:17:29 [ERROR]: Added missing column: Text
2025-04-08 21:17:29 [ERROR]: Using Current Display as the source for text data
2025-04-08 21:17:29 [ERROR]: Actual text source column identified as: Current Display
2025-04-08 21:17:32 [ERROR]: Using metadata headers from preset 'Standard Metadata': Document Type;Author;Correspondent;Correspondent Place;Date;Place of Creation;People;Places;Summary
2025-04-08 21:17:32 [ERROR]: Added essential column: Creation_Place
2025-04-08 21:17:32 [ERROR]: Metadata columns to copy: ['Document_Type', 'Author', 'Correspondent', 'Correspondent_Place', 'Date', 'Place_of_Creation', 'People', 'Places', 'Summary', 'Creation_Place']
2025-04-08 21:17:32 [ERROR]: Copied 8 values for column: Document_Type
2025-04-08 21:17:32 [ERROR]: Copied 8 values for column: Author
2025-04-08 21:17:32 [ERROR]: Copied 8 values for column: Correspondent
2025-04-08 21:17:32 [ERROR]: Copied 8 values for column: Correspondent_Place
2025-04-08 21:17:32 [ERROR]: Copied 8 values for column: Date
2025-04-08 21:17:32 [ERROR]: Copied 8 values for column: Place_of_Creation
2025-04-08 21:17:32 [ERROR]: Copied 8 values for column: People
2025-04-08 21:17:32 [ERROR]: Copied 8 values for column: Places
2025-04-08 21:17:32 [ERROR]: Copied 8 values for column: Summary
2025-04-08 21:17:32 [ERROR]: Copied 8 values for column: Creation_Place
2025-04-08 21:17:32 [ERROR]: Preparing export dataframe. Text source: Current Display
2025-04-08 21:17:32 [ERROR]: Using 'Current Display' for text - applying find_right_text
2025-04-08 21:17:32 [ERROR]: Metadata headers from preset 'Standard Metadata': ['Document_Type', 'Author', 'Correspondent', 'Correspondent_Place', 'Date', 'Place_of_Creation', 'People', 'Places', 'Summary']
2025-04-08 21:17:32 [ERROR]: Final ordered columns for export: ['Page', 'Author', 'Document_Type', 'Correspondent', 'Correspondent_Place', 'Date', 'Place_of_Creation', 'People', 'Places', 'Summary', 'Original_Text']
2025-04-08 21:23:52 [ERROR]: Resolved 'Current Display' to actual column: Original_Text
2025-04-08 21:23:55 [ERROR]: Starting CSV export process
2025-04-08 21:23:55 [ERROR]: Ensuring these columns exist in the DataFrame: ['Page', 'Text', 'Citation', 'Document_Type', 'Author', 'Correspondent', 'Correspondent_Place', 'Date', 'Place_of_Creation', 'People', 'Places', 'Summary', 'People', 'Places', 'Translation', 'Separated_Text', 'Creation_Place', 'Date']
2025-04-08 21:23:55 [ERROR]: Added missing column: Place_of_Creation
2025-04-08 21:23:55 [ERROR]: Added missing column: Text
2025-04-08 21:23:55 [ERROR]: Using Original_Text as the source for text data
2025-04-08 21:23:55 [ERROR]: Actual text source column identified as: Original_Text
2025-04-08 21:23:55 [ERROR]: Critical error in metadata generation: name 'actual_text_source_column' is not defined
Stack trace:
Traceback (most recent call last):
  File "d:\TranscriptionPearl\util\ExportFunctions.py", line 633, in _generate_metadata
    export_text_source=actual_text_source_column # Pass resolved source column
                       ^^^^^^^^^^^^^^^^^^^^^^^^^
NameError: name 'actual_text_source_column' is not defined
2025-04-08 21:23:55 [ERROR]: Traceback: Traceback (most recent call last):
  File "d:\TranscriptionPearl\util\ExportFunctions.py", line 633, in _generate_metadata
    export_text_source=actual_text_source_column # Pass resolved source column
                       ^^^^^^^^^^^^^^^^^^^^^^^^^
NameError: name 'actual_text_source_column' is not defined

Stack trace:
Traceback (most recent call last):
  File "d:\TranscriptionPearl\util\ExportFunctions.py", line 633, in _generate_metadata
    export_text_source=actual_text_source_column # Pass resolved source column
                       ^^^^^^^^^^^^^^^^^^^^^^^^^
NameError: name 'actual_text_source_column' is not defined
2025-04-08 21:23:56 [ERROR]: Preparing export dataframe. Text source: Original_Text
2025-04-08 21:23:56 [ERROR]: Using column 'Original_Text' for text
2025-04-08 21:23:56 [ERROR]: Dropped original text source column: Original_Text
2025-04-08 21:23:56 [ERROR]: Metadata headers from preset 'Standard Metadata': ['Document_Type', 'Author', 'Correspondent', 'Correspondent_Place', 'Date', 'Place_of_Creation', 'People', 'Places', 'Summary']
2025-04-08 21:23:56 [ERROR]: 'Original_Text' column is missing before final ordering.
2025-04-08 21:23:56 [ERROR]: CRITICAL: 'Original_Text' column missing in final export list!
2025-04-08 21:23:56 [ERROR]: Final ordered columns for export: ['Page', 'Author', 'Document_Type', 'Correspondent', 'Correspondent_Place', 'Date', 'Place_of_Creation', 'People', 'Places', 'Summary']
2025-04-08 21:25:11 [ERROR]: Resolved 'Current Display' to actual column: Original_Text
2025-04-08 21:25:14 [ERROR]: Starting CSV export process
2025-04-08 21:25:14 [ERROR]: Ensuring these columns exist in the DataFrame: ['Page', 'Text', 'Citation', 'Document_Type', 'Author', 'Correspondent', 'Correspondent_Place', 'Date', 'Place_of_Creation', 'People', 'Places', 'Summary', 'People', 'Places', 'Translation', 'Separated_Text', 'Creation_Place', 'Date']
2025-04-08 21:25:14 [ERROR]: Added missing column: Place_of_Creation
2025-04-08 21:25:14 [ERROR]: Added missing column: Text
2025-04-08 21:25:14 [ERROR]: Using Original_Text as the source for text data
2025-04-08 21:25:14 [ERROR]: Actual text source column identified as: Original_Text
2025-04-08 21:26:05 [ERROR]: Critical error in metadata generation: cannot access local variable 'job_params' where it is not associated with a value
Stack trace:
Traceback (most recent call last):
  File "d:\TranscriptionPearl\util\ExportFunctions.py", line 634, in _generate_metadata
  File "d:\TranscriptionPearl\util\AIFunctions.py", line 493, in ai_function
    self.last_used_metadata_preset = job_params.get('preset_name_used', None)
                                     ^^^^^^^^^^
UnboundLocalError: cannot access local variable 'job_params' where it is not associated with a value
2025-04-08 21:26:05 [ERROR]: Traceback: Traceback (most recent call last):
  File "d:\TranscriptionPearl\util\ExportFunctions.py", line 634, in _generate_metadata
  File "d:\TranscriptionPearl\util\AIFunctions.py", line 493, in ai_function
    self.last_used_metadata_preset = job_params.get('preset_name_used', None)
                                     ^^^^^^^^^^
UnboundLocalError: cannot access local variable 'job_params' where it is not associated with a value

Stack trace:
Traceback (most recent call last):
  File "d:\TranscriptionPearl\util\ExportFunctions.py", line 634, in _generate_metadata
  File "d:\TranscriptionPearl\util\AIFunctions.py", line 493, in ai_function
    self.last_used_metadata_preset = job_params.get('preset_name_used', None)
                                     ^^^^^^^^^^
UnboundLocalError: cannot access local variable 'job_params' where it is not associated with a value
2025-04-08 21:26:05 [ERROR]: Preparing export dataframe. Text source: Original_Text
2025-04-08 21:26:05 [ERROR]: Using column 'Original_Text' for text
2025-04-08 21:26:05 [ERROR]: Dropped original text source column: Original_Text
2025-04-08 21:26:05 [ERROR]: Metadata headers from preset 'Standard Metadata': ['Document_Type', 'Author', 'Correspondent', 'Correspondent_Place', 'Date', 'Place_of_Creation', 'People', 'Places', 'Summary']
2025-04-08 21:26:05 [ERROR]: 'Original_Text' column is missing before final ordering.
2025-04-08 21:26:05 [ERROR]: CRITICAL: 'Original_Text' column missing in final export list!
2025-04-08 21:26:05 [ERROR]: Final ordered columns for export: ['Page', 'Author', 'Document_Type', 'Correspondent', 'Correspondent_Place', 'Date', 'Place_of_Creation', 'People', 'Places', 'Summary']
2025-04-08 21:26:23 [ERROR]: Resolved 'Current Display' to actual column: Original_Text
2025-04-08 21:26:28 [ERROR]: Starting CSV export process
2025-04-08 21:26:28 [ERROR]: Ensuring these columns exist in the DataFrame: ['Page', 'Text', 'Citation', 'Document_Type', 'Author', 'Correspondent', 'Correspondent_Place', 'Date', 'Place_of_Creation', 'People', 'Places', 'Summary', 'People', 'Places', 'Translation', 'Separated_Text', 'Creation_Place', 'Date']
2025-04-08 21:26:28 [ERROR]: Added missing column: Place_of_Creation
2025-04-08 21:26:28 [ERROR]: Added missing column: Text
2025-04-08 21:26:28 [ERROR]: Using resolved text source column: Original_Text
2025-04-08 21:26:29 [ERROR]: Critical error in metadata generation: cannot access local variable 'job_params' where it is not associated with a value
Stack trace:
Traceback (most recent call last):
  File "d:\TranscriptionPearl\util\ExportFunctions.py", line 623, in _generate_metadata
    self.app.ai_functions_handler.ai_function(
  File "d:\TranscriptionPearl\util\AIFunctions.py", line 493, in ai_function
    self.last_used_metadata_preset = job_params.get('preset_name_used', None)
                                     ^^^^^^^^^^
UnboundLocalError: cannot access local variable 'job_params' where it is not associated with a value
2025-04-08 21:26:29 [ERROR]: Traceback: Traceback (most recent call last):
  File "d:\TranscriptionPearl\util\ExportFunctions.py", line 623, in _generate_metadata
    self.app.ai_functions_handler.ai_function(
  File "d:\TranscriptionPearl\util\AIFunctions.py", line 493, in ai_function
    self.last_used_metadata_preset = job_params.get('preset_name_used', None)
                                     ^^^^^^^^^^
UnboundLocalError: cannot access local variable 'job_params' where it is not associated with a value

Stack trace:
Traceback (most recent call last):
  File "d:\TranscriptionPearl\util\ExportFunctions.py", line 623, in _generate_metadata
    self.app.ai_functions_handler.ai_function(
  File "d:\TranscriptionPearl\util\AIFunctions.py", line 493, in ai_function
    self.last_used_metadata_preset = job_params.get('preset_name_used', None)
                                     ^^^^^^^^^^
UnboundLocalError: cannot access local variable 'job_params' where it is not associated with a value
2025-04-08 21:26:29 [ERROR]: Preparing export dataframe. Text source: Original_Text
2025-04-08 21:26:29 [ERROR]: Using column 'Original_Text' for text
2025-04-08 21:26:29 [ERROR]: Dropped original text source column: Original_Text
2025-04-08 21:26:29 [ERROR]: Metadata headers from preset 'Standard Metadata': ['Document_Type', 'Author', 'Correspondent', 'Correspondent_Place', 'Date', 'Place_of_Creation', 'People', 'Places', 'Summary']
2025-04-08 21:26:29 [ERROR]: 'Original_Text' column is missing before final ordering.
2025-04-08 21:26:29 [ERROR]: CRITICAL: 'Original_Text' column missing in final export list!
2025-04-08 21:26:29 [ERROR]: Final ordered columns for export: ['Page', 'Author', 'Document_Type', 'Correspondent', 'Correspondent_Place', 'Date', 'Place_of_Creation', 'People', 'Places', 'Summary']
2025-04-08 21:29:19 [ERROR]: Resolved 'Current Display' to actual column: Original_Text
2025-04-08 21:29:22 [ERROR]: Starting CSV export process
2025-04-08 21:29:22 [ERROR]: Ensuring these columns exist in the DataFrame: ['Page', 'Text', 'Citation', 'Document_Type', 'Author', 'Correspondent', 'Correspondent_Place', 'Date', 'Place_of_Creation', 'People', 'Places', 'Summary', 'People', 'Places', 'Translation', 'Separated_Text', 'Creation_Place', 'Date']
2025-04-08 21:29:22 [ERROR]: Added missing column: Place_of_Creation
2025-04-08 21:29:22 [ERROR]: Added missing column: Text
2025-04-08 21:29:22 [ERROR]: Using resolved text source column: Original_Text
2025-04-08 21:29:24 [ERROR]: Using metadata headers from preset 'Standard Metadata': Document Type;Author;Correspondent;Correspondent Place;Date;Place of Creation;People;Places;Summary
2025-04-08 21:29:24 [ERROR]: Added essential column: Creation_Place
2025-04-08 21:29:24 [ERROR]: Metadata columns to copy: ['Document_Type', 'Author', 'Correspondent', 'Correspondent_Place', 'Date', 'Place_of_Creation', 'People', 'Places', 'Summary', 'Creation_Place']
2025-04-08 21:29:24 [ERROR]: Copied 8 values for column: Document_Type
2025-04-08 21:29:24 [ERROR]: Copied 8 values for column: Author
2025-04-08 21:29:24 [ERROR]: Copied 8 values for column: Correspondent
2025-04-08 21:29:24 [ERROR]: Copied 8 values for column: Correspondent_Place
2025-04-08 21:29:24 [ERROR]: Copied 8 values for column: Date
2025-04-08 21:29:24 [ERROR]: Copied 8 values for column: Place_of_Creation
2025-04-08 21:29:24 [ERROR]: Copied 8 values for column: People
2025-04-08 21:29:24 [ERROR]: Copied 8 values for column: Places
2025-04-08 21:29:24 [ERROR]: Copied 8 values for column: Summary
2025-04-08 21:29:24 [ERROR]: Copied 8 values for column: Creation_Place
2025-04-08 21:29:24 [ERROR]: Preparing export dataframe. Text source: Original_Text
2025-04-08 21:29:24 [ERROR]: Using column 'Original_Text' for text
2025-04-08 21:29:24 [ERROR]: Dropped original text source column: Original_Text
2025-04-08 21:29:24 [ERROR]: Metadata headers from preset 'Standard Metadata': ['Document_Type', 'Author', 'Correspondent', 'Correspondent_Place', 'Date', 'Place_of_Creation', 'People', 'Places', 'Summary']
2025-04-08 21:29:24 [ERROR]: 'Original_Text' column is missing before final ordering.
2025-04-08 21:29:24 [ERROR]: CRITICAL: 'Original_Text' column missing in final export list!
2025-04-08 21:29:24 [ERROR]: Final ordered columns for export: ['Page', 'Author', 'Document_Type', 'Correspondent', 'Correspondent_Place', 'Date', 'Place_of_Creation', 'People', 'Places', 'Summary']
2025-04-08 21:29:49 [ERROR]: Resolved 'Current Display' to actual column: Original_Text
2025-04-08 21:29:53 [ERROR]: Starting CSV export process
2025-04-08 21:29:53 [ERROR]: Ensuring these columns exist in the DataFrame: ['Page', 'Text', 'Citation', 'Document_Type', 'Author', 'Correspondent', 'Correspondent_Place', 'Date', 'Place_of_Creation', 'People', 'Places', 'Summary', 'People', 'Places', 'Translation', 'Separated_Text', 'Creation_Place', 'Date']
2025-04-08 21:29:53 [ERROR]: Added missing column: Place_of_Creation
2025-04-08 21:29:53 [ERROR]: Added missing column: Text
2025-04-08 21:29:53 [ERROR]: Using resolved text source column: Original_Text
2025-04-08 21:30:01 [ERROR]: Using metadata headers from preset 'Standard Metadata': Document Type;Author;Correspondent;Correspondent Place;Date;Place of Creation;People;Places;Summary
2025-04-08 21:30:01 [ERROR]: Added essential column: Creation_Place
2025-04-08 21:30:01 [ERROR]: Metadata columns to copy: ['Document_Type', 'Author', 'Correspondent', 'Correspondent_Place', 'Date', 'Place_of_Creation', 'People', 'Places', 'Summary', 'Creation_Place']
2025-04-08 21:30:01 [ERROR]: Copied 8 values for column: Document_Type
2025-04-08 21:30:01 [ERROR]: Copied 8 values for column: Author
2025-04-08 21:30:01 [ERROR]: Copied 8 values for column: Correspondent
2025-04-08 21:30:01 [ERROR]: Copied 8 values for column: Correspondent_Place
2025-04-08 21:30:01 [ERROR]: Copied 8 values for column: Date
2025-04-08 21:30:01 [ERROR]: Copied 8 values for column: Place_of_Creation
2025-04-08 21:30:01 [ERROR]: Copied 8 values for column: People
2025-04-08 21:30:01 [ERROR]: Copied 8 values for column: Places
2025-04-08 21:30:01 [ERROR]: Copied 8 values for column: Summary
2025-04-08 21:30:01 [ERROR]: Copied 8 values for column: Creation_Place
2025-04-08 21:30:01 [ERROR]: Single author specified: Jhn Cobb
2025-04-08 21:30:01 [ERROR]: Citation specified: HBCA
2025-04-08 21:30:01 [ERROR]: Starting date and place analysis sequence using preset: Sequence_Dates
2025-04-08 21:30:01 [ERROR]: Using required headers from sequential preset: ['Date', 'Place']
2025-04-08 21:30:01 [ERROR]: Clearing existing values for fresh date analysis
2025-04-08 21:30:01 [ERROR]: Copied existing Date values from compiled_df to date_df
2025-04-08 21:30:01 [ERROR]: Added legacy Creation_Place column to date_df
2025-04-08 21:30:01 [ERROR]: Created date analysis dataframe with 8 rows and columns: ['Page', 'Text', 'Date', 'Place', 'Creation_Place']
2025-04-08 21:30:01 [ERROR]: Using specified sequential preset: Sequence_Dates
2025-04-08 21:30:01 [ERROR]: Found required headers in sequence preset: ['Date', 'Place']
2025-04-08 21:30:01 [ERROR]: Setting active sequential preset to: Sequence_Dates
2025-04-08 21:30:22 [ERROR]: Date analysis result dataframe has columns: ['Page', 'Text', 'Date', 'Place', 'Creation_Place']
2025-04-08 21:30:22 [ERROR]: Date analysis result dataframe has 8 rows
2025-04-08 21:30:22 [ERROR]: Date analysis found 8 dates
2025-04-08 21:30:22 [ERROR]: Date analysis found 8 Date values
2025-04-08 21:30:22 [ERROR]: Date analysis found 8 Place values
2025-04-08 21:30:22 [ERROR]: Sample row 0: {'Page': np.int64(0), 'Text': 'A Journal of Transactions at\nAsh Fall by Mr John Cobb\n1', 'Date': 'YYYY/MM/DD', 'Place': 'Ash Fall', 'Creation_Place': 'Ash Fall'}
2025-04-08 21:30:22 [ERROR]: Sample row 1: {'Page': np.int64(1), 'Text': '1798.\nAugt 2 Thursday Wind Westerly clear pleasant weather at 2 P. M.\nI set off from Martins Fall with two Boats for Osnaburgh\nHouse and arrived at that place the 19 Inst.', 'Date': '1798/08/02', 'Place': 'Martins Fall', 'Creation_Place': 'Martins Fall'}
2025-04-08 21:30:22 [ERROR]: Sample row 2: {'Page': np.int64(2), 'Text': '20 Monday Wind N Wst with rain all day in the evening\nMr McKay arrived from Martins Fall with 3 Boats', 'Date': '1798/08/20', 'Place': 'Osnaburgh House', 'Creation_Place': 'Osnaburgh House'}
2025-04-08 21:30:22 [ERROR]: Date analysis returned dataframe with columns: Page, Text, Date, Place, Creation_Place
2025-04-08 21:30:22 [ERROR]: Sample row 0: {'Page': np.int64(0), 'Text': 'A Journal of Transactions at\nAsh Fall by Mr John Cobb\n1', 'Date': 'YYYY/MM/DD', 'Place': 'Ash Fall', 'Creation_Place': 'Ash Fall'}
2025-04-08 21:30:22 [ERROR]: Sample row 1: {'Page': np.int64(1), 'Text': '1798.\nAugt 2 Thursday Wind Westerly clear pleasant weather at 2 P. M.\nI set off from Martins Fall with two Boats for Osnaburgh\nHouse and arrived at that place the 19 Inst.', 'Date': '1798/08/02', 'Place': 'Martins Fall', 'Creation_Place': 'Martins Fall'}
2025-04-08 21:30:22 [ERROR]: Sample row 2: {'Page': np.int64(2), 'Text': '20 Monday Wind N Wst with rain all day in the evening\nMr McKay arrived from Martins Fall with 3 Boats', 'Date': '1798/08/20', 'Place': 'Osnaburgh House', 'Creation_Place': 'Osnaburgh House'}
2025-04-08 21:30:22 [ERROR]: Using specified sequential preset for copying results: Sequence_Dates
2025-04-08 21:30:22 [ERROR]: Copying required headers from sequence preset: ['Date', 'Place']
2025-04-08 21:30:22 [ERROR]: Added missing Place column to compiled_df before copying results
2025-04-08 21:30:22 [ERROR]: Updated fields in the compiled dataframe: 8 Date, 8 Place, 8 Place_of_Creation, 8 Creation_Place
2025-04-08 21:30:22 [ERROR]: Sequential preset headers: ['Date', 'Place']
2025-04-08 21:30:22 [ERROR]: Preparing export dataframe. Text source: Original_Text
2025-04-08 21:30:22 [ERROR]: Using column 'Original_Text' for text
2025-04-08 21:30:22 [ERROR]: Dropped original text source column: Original_Text
2025-04-08 21:30:22 [ERROR]: Overriding 'Author' column with single author: Jhn Cobb
2025-04-08 21:30:22 [ERROR]: Metadata headers from preset 'Standard Metadata': ['Document_Type', 'Author', 'Correspondent', 'Correspondent_Place', 'Date', 'Place_of_Creation', 'People', 'Places', 'Summary']
2025-04-08 21:30:22 [ERROR]: Adding/overwriting with sequential headers: ['Date', 'Place']
2025-04-08 21:30:22 [ERROR]: 'Original_Text' column is missing before final ordering.
2025-04-08 21:30:22 [ERROR]: Adding 'Citation' column.
2025-04-08 21:30:22 [ERROR]: CRITICAL: 'Original_Text' column missing in final export list!
2025-04-08 21:30:22 [ERROR]: Final ordered columns for export: ['Page', 'Author', 'Document_Type', 'Correspondent', 'Correspondent_Place', 'Date', 'Place_of_Creation', 'People', 'Places', 'Summary', 'Place', 'Citation']
2025-04-08 22:09:19 [ERROR]: Critical error in collate_names_and_places: '_tkinter.tkapp' object has no attribute 'parse_collation_response'
Stack trace:
Traceback (most recent call last):
  File "d:\TranscriptionPearl\util\AIFunctions.py", line 861, in collate_names_and_places
    names_dict = self.app.parse_collation_response(self.collated_names_raw)
                 ^^^^^^^^^^^^^^^^^^^^^^^^^^^^^^^^^
  File "C:\Users\mark_\anaconda3\envs\TranscriptionPearl\Lib\tkinter\__init__.py", line 2433, in __getattr__
    return getattr(self.tk, attr)
           ^^^^^^^^^^^^^^^^^^^^^^
AttributeError: '_tkinter.tkapp' object has no attribute 'parse_collation_response'
2025-04-09 18:59:18 [ERROR]: Process edited image error: [WinError 183] Cannot create a file when that file already exists: 'd:\\TranscriptionPearl\\util\\temp\\images\\temp_0_0.jpg' -> 'd:\\TranscriptionPearl\\util\\temp\\images\\0001_p001.jpg'
Stack trace:
Traceback (most recent call last):
  File "d:\TranscriptionPearl\util\DataOperations.py", line 572, in process_edited_single_image
    os.rename(old_temp_path_abs, final_image_path_abs)
FileExistsError: [WinError 183] Cannot create a file when that file already exists: 'd:\\TranscriptionPearl\\util\\temp\\images\\temp_0_0.jpg' -> 'd:\\TranscriptionPearl\\util\\temp\\images\\0001_p001.jpg'
2025-04-09 19:00:29 [ERROR]: Process edited image error: [WinError 183] Cannot create a file when that file already exists: 'd:\\TranscriptionPearl\\util\\temp\\images\\temp_0_0.jpg' -> 'd:\\TranscriptionPearl\\util\\temp\\images\\0001_p001.jpg'
Stack trace:
Traceback (most recent call last):
  File "d:\TranscriptionPearl\util\DataOperations.py", line 572, in process_edited_single_image
    os.rename(old_temp_path_abs, final_image_path_abs)
FileExistsError: [WinError 183] Cannot create a file when that file already exists: 'd:\\TranscriptionPearl\\util\\temp\\images\\temp_0_0.jpg' -> 'd:\\TranscriptionPearl\\util\\temp\\images\\0001_p001.jpg'
2025-04-09 19:36:46 [ERROR]: Process edited image error: [WinError 183] Cannot create a file when that file already exists: 'd:\\TranscriptionPearl\\util\\temp\\images\\temp_0_0.jpg' -> 'd:\\TranscriptionPearl\\util\\temp\\images\\0001_p001.jpg'
Stack trace:
Traceback (most recent call last):
  File "d:\TranscriptionPearl\util\DataOperations.py", line 572, in process_edited_single_image
    os.rename(old_temp_path_abs, final_image_path_abs)
FileExistsError: [WinError 183] Cannot create a file when that file already exists: 'd:\\TranscriptionPearl\\util\\temp\\images\\temp_0_0.jpg' -> 'd:\\TranscriptionPearl\\util\\temp\\images\\0001_p001.jpg'
2025-04-09 19:40:21 [ERROR]: Error in edit_all_images: name 'natural_sort_key' is not defined
Stack trace:
Traceback (most recent call last):
  File "d:\TranscriptionPearl\TranscriptionPearl_beta-dev.py", line 2431, in edit_all_images
    key=natural_sort_key # Sort naturally
        ^^^^^^^^^^^^^^^^
NameError: name 'natural_sort_key' is not defined
